Workbook

Sheet 首頁
C3: 資料匯出報表目錄 | T3: 46022 | U3: 新年快樂～
C6: 序號 | D6: 表索引 | E6: 描述 | F6: 連結 | G6: 宥婕 | H6: 瀚平 | I6: 賀翔 | J6: 尚書 | K6: 文琪 | L6: 育誠 | M6: 會議
C7: 1 | D7: 表 1‑1 | E7: 全國住宅使用現況－按地區分 | F7: 查看 | G7: ='表 1‑1'!C3 -> ➖ | H7: ='表 1‑1'!C4 -> ➖ | I7: ='表 1‑1'!C5 -> ➖ | J7: ='表 1‑1'!C6 -> ➖ | K7: ='表 1‑1'!C7 -> ➖ | L7: ='表 1‑1'!C8 -> ➖ | M7: ='表 1‑1'!C9 -> ➖
C8: 2 | D8: 表 1‑2 | E8: 全國住宅使用現況－按建物總樓層分 | F8: 查看 | G8: ='表 1‑2'!C3 -> ➖ | H8: ='表 1‑2'!C4 -> ➖ | I8: ='表 1‑2'!C5 -> ➖ | J8: ='表 1‑2'!C6 -> ➖ | K8: ='表 1‑2'!C7 -> ➖ | L8: ='表 1‑2'!C8 -> ➖ | M8: ='表 1‑2'!C9 -> ➖ | N8: 低度 | O8: 連江縣 8.7% 較 23 年新增 2.39%，為全國最多
C9: 3 | D9: 表 1‑3 | E9: 全國住宅使用現況－按建物屋齡分 | F9: 查看 | G9: ='表 1‑3'!C3 -> ➖ | H9: ='表 1‑3'!C4 -> ➖ | I9: ='表 1‑3'!C5 -> ➖ | J9: ='表 1‑3'!C6 -> ➖ | K9: ='表 1‑3'!C7 -> ➖ | L9: ='表 1‑3'!C8 -> ➖ | M9: ='表 1‑3'!C9 -> ➖
C10: 4 | D10: 表 1‑4 | E10: 全國住宅使用現況－按建物面積分 | F10: 查看 | G10: ='表 1‑4'!C3 -> ➖ | H10: ='表 1‑4'!C4 -> ➖ | I10: ='表 1‑4'!C5 -> ➖ | J10: ='表 1‑4'!C6 -> ➖ | K10: ='表 1‑4'!C7 -> ➖ | L10: ='表 1‑4'!C8 -> ➖ | M10: ='表 1‑4'!C9 -> ➖ | P10: 低度用電 | Q10: 非低度用電 | R10: 總計 | U10: 低度用電 | V10: 非低度用電 | W10: 總計
C11: 5 | D11: 表 1‑5 | E11: 全國住宅使用現況－按建物使用類別分 | F11: 查看 | G11: ='表 1‑5'!C3 -> ➖ | H11: ='表 1‑5'!C4 -> ➖ | I11: ='表 1‑5'!C5 -> ➖ | J11: ='表 1‑5'!C6 -> ➖ | K11: ='表 1‑5'!C7 -> ➖ | L11: ='表 1‑5'!C8 -> ➖ | M11: ='表 1‑5'!C9 -> ➖ | O11: 連江縣 | P11: 8.6956522 | Q11: 91.304348 | R11: 100 | T11: 連江縣 | U11: 2.3893459 | V11: -2.3893459 | W11: 0
C12: 6 | D12: 表 1‑6 | E12: 全國住宅使用現況－按建物結構分 | F12: 查看 | G12: ='表 1‑6'!C3 -> ➖ | H12: ='表 1‑6'!C4 -> ➖ | I12: ='表 1‑6'!C5 -> ➖ | J12: ='表 1‑6'!C6 -> ➖ | K12: ='表 1‑6'!C7 -> ➖ | L12: ='表 1‑6'!C8 -> ➖ | M12: ='表 1‑6'!C9 -> ➖ | O12: 總計 | P12: 8.8219416 | Q12: 91.178058 | R12: 100 | T12: 總計 | U12: 0.46572446 | V12: -0.46572446 | W12: 0
C13: 7 | D13: 表 1‑7 | E13: 各地區住宅分布－按建物屋齡分 | F13: 查看 | G13: ='表 1‑7'!C3 -> ➖ | H13: ='表 1‑7'!C4 -> ➖ | I13: ='表 1‑7'!C5 -> ➖ | J13: ='表 1‑7'!C6 -> ➖ | K13: ='表 1‑7'!C7 -> ➖ | L13: ='表 1‑7'!C8 -> ➖ | M13: ='表 1‑7'!C9 -> ➖
C14: 8 | D14: 表 1‑8 | E14: 各地區住宅分布－按建物面積（坪）分 | F14: 查看 | G14: ='表 1‑8'!C3 -> ➖ | H14: ='表 1‑8'!C4 -> ➖ | I14: ='表 1‑8'!C5 -> ➖ | J14: ='表 1‑8'!C6 -> ➖ | K14: ='表 1‑8'!C7 -> ➖ | L14: ='表 1‑8'!C8 -> ➖ | M14: ='表 1‑8'!C9 -> ➖
C15: 9 | D15: 表 1‑9 | E15: 各地區住宅分布－按建物總樓層分 | F15: 查看 | G15: ='表 1‑9'!C3 -> ➖ | H15: ='表 1‑9'!C4 -> ➖ | I15: ='表 1‑9'!C5 -> ➖ | J15: ='表 1‑9'!C6 -> ➖ | K15: ='表 1‑9'!C7 -> ➖ | L15: ='表 1‑9'!C8 -> ➖ | M15: ='表 1‑9'!C9 -> ➖
C16: 10 | D16: 表 1‑10 | E16: 各地區住宅分布－按建物使用類別分 | F16: 查看 | G16: ='表 1‑10'!C3 -> ➖ | H16: ='表 1‑10'!C4 -> ➖ | I16: ='表 1‑10'!C5 -> ➖ | J16: ='表 1‑10'!C6 -> ➖ | K16: ='表 1‑10'!C7 -> ➖ | L16: ='表 1‑10'!C8 -> ➖ | M16: ='表 1‑10'!C9 -> ➖ | N16: 2024 | P16: 0~4年 | Q16: 5~9年 | R16: 10~19年 | S16: 20~29年 | T16: 30~39年 | U16: 40~49年 | V16: 50年以上 | W16: 總計
C17: 11 | D17: 表 1‑11 | E17: 各地區住宅分布－按建物結構分 | F17: 查看 | G17: ='表 1‑11'!C3 -> ➖ | H17: ='表 1‑11'!C4 -> ➖ | I17: ='表 1‑11'!C5 -> ➖ | J17: ='表 1‑11'!C6 -> ➖ | K17: ='表 1‑11'!C7 -> ➖ | L17: ='表 1‑11'!C8 -> ➖ | M17: ='表 1‑11'!C9 -> ➖ | N17: n=785 | O17: 連江縣 | P17: 35.149157 | Q17: 15.175097 | R17: 14.785992 | S17: 7.6523995 | T17: 4.7989624 | U17: 10.894942 | V17: 11.54345 | W17: 100
C18: 12 | D18: 表 1‑12 | E18: 各建物屋齡分布－按建物面積（坪）分 | F18: 查看 | G18: ='表 1‑12'!C3 -> ➖ | H18: ='表 1‑12'!C4 -> ➖ | I18: ='表 1‑12'!C5 -> ➖ | J18: ='表 1‑12'!C6 -> ➖ | K18: ='表 1‑12'!C7 -> ➖ | L18: ='表 1‑12'!C8 -> ➖ | M18: ='表 1‑12'!C9 -> ➖ | N18: n=9,133,942 | O18: 總計 | P18: 6.3344691 | Q18: 6.2033561 | R18: 13.319329 | S18: 20.961784 | T18: 22.380628 | U18: 23.634202 | V18: 7.1662321 | W18: 100
C19: 13 | D19: 表 1‑13 | E19: 各建物屋齡分布－按建物總樓層分 | F19: 查看 | G19: ='表 1‑13'!C3 -> ➖ | H19: ='表 1‑13'!C4 -> ➖ | I19: ='表 1‑13'!C5 -> ➖ | J19: ='表 1‑13'!C6 -> ➖ | K19: ='表 1‑13'!C7 -> ➖ | L19: ='表 1‑13'!C8 -> ➖ | M19: ='表 1‑13'!C9 -> ➖ | N19: 新增% | P19: 0~4年 | Q19: 5~9年 | R19: 10~19年 | S19: 20~29年 | T19: 30~39年 | U19: 40~49年 | V19: 50年以上 | W19: 總計
C20: 14 | D20: 表 1‑14 | E20: 各建物屋齡分布－按建物使用類別 | F20: 查看 | G20: ='表 1‑14'!C3 -> ➖ | H20: ='表 1‑14'!C4 -> ➖ | I20: ='表 1‑14'!C5 -> ➖ | J20: ='表 1‑14'!C6 -> ➖ | K20: ='表 1‑14'!C7 -> ➖ | L20: ='表 1‑14'!C8 -> ➖ | M20: ='表 1‑14'!C9 -> ➖ | N20: n=232 | O20: 連江縣 | P20: 21.420029 | Q20: -2.0790771 | R20: -5.622171 | S20: -2.5516822 | T20: -3.3643029 | U20: -3.3907727 | V20: -4.412023 | W20: 0
C21: 15 | D21: 表 1‑15 | E21: 各建物屋齡分布－按建物結構分 | F21: 查看 | G21: ='表 1‑15'!C3 -> ➖ | H21: ='表 1‑15'!C4 -> ➖ | I21: ='表 1‑15'!C5 -> ➖ | J21: ='表 1‑15'!C6 -> ➖ | K21: ='表 1‑15'!C7 -> ➖ | L21: ='表 1‑15'!C8 -> ➖ | M21: ='表 1‑15'!C9 -> ➖ | N21: n=148,880 | O21: 總計 | P21: 0.35586144 | Q21: -0.1352944 | R21: -0.42783219 | S21: -3.7637401 | T21: 2.3569035 | U21: 0.48422759 | V21: 1.1298742 | W21: 0
C22: 16 | D22: 表 1‑16 | E22: 各建物面積（坪）分布－按建物總樓層分 | F22: 查看 | G22: ='表 1‑16'!C3 -> ➖ | H22: ='表 1‑16'!C4 -> ➖ | I22: ='表 1‑16'!C5 -> ➖ | J22: ='表 1‑16'!C6 -> ➖ | K22: ='表 1‑16'!C7 -> ➖ | L22: ='表 1‑16'!C8 -> ➖ | M22: ='表 1‑16'!C9 -> ➖
C23: 17 | D23: 表 1‑17 | E23: 各建物面積（坪）分布－按建物使用類別分 | F23: 查看 | G23: ='表 1‑17'!C3 -> ➖ | H23: ='表 1‑17'!C4 -> ➖ | I23: ='表 1‑17'!C5 -> ➖ | J23: ='表 1‑17'!C6 -> ➖ | K23: ='表 1‑17'!C7 -> ➖ | L23: ='表 1‑17'!C8 -> ➖ | M23: ='表 1‑17'!C9 -> ➖
C24: 18 | D24: 表 1‑18 | E24: 各建物面積（坪）分布－按建物結構分 | F24: 查看 | G24: ='表 1‑18'!C3 -> ➖ | H24: ='表 1‑18'!C4 -> ➖ | I24: ='表 1‑18'!C5 -> ➖ | J24: ='表 1‑18'!C6 -> ➖ | K24: ='表 1‑18'!C7 -> ➖ | L24: ='表 1‑18'!C8 -> ➖ | M24: ='表 1‑18'!C9 -> ➖ | P24: 0~19坪 | Q24: 20~29坪 | R24: 30~39坪 | S24: 40~49坪 | T24: 50~59坪 | U24: 60~69坪 | V24: 70坪以上 | W24: 總計
C25: 19 | D25: 表 1‑19 | E25: 各建物總樓層分布－按建物使用類別分 | F25: 查看 | G25: ='表 1‑19'!C3 -> ➖ | H25: ='表 1‑19'!C4 -> ➖ | I25: ='表 1‑19'!C5 -> ➖ | J25: ='表 1‑19'!C6 -> ➖ | K25: ='表 1‑19'!C7 -> ➖ | L25: ='表 1‑19'!C8 -> ➖ | M25: ='表 1‑19'!C9 -> ➖ | O25: 連江縣 | P25: 12.484076 | Q25: 15.796178 | R25: 21.910828 | S25: 21.146497 | T25: 4.4585987 | U25: 3.9490446 | V25: 20.254777 | W25: 100
C26: 20 | D26: 表 1‑20 | E26: 各建物總樓層分布－按建物結構分 | F26: 查看 | G26: ='表 1‑20'!C3 -> ➖ | H26: ='表 1‑20'!C4 -> ➖ | I26: ='表 1‑20'!C5 -> ➖ | J26: ='表 1‑20'!C6 -> ➖ | K26: ='表 1‑20'!C7 -> ➖ | L26: ='表 1‑20'!C8 -> ➖ | M26: ='表 1‑20'!C9 -> ➖ | O26: 總計 | P26: 15.904316 | Q26: 30.924096 | R26: 20.304016 | S26: 9.2201374 | T26: 7.7821383 | U26: 4.994284 | V26: 10.871013 | W26: 100
C27: 21 | D27: 表 1‑21 | E27: 各建物使用類別分布－按建物結構分 | F27: 查看 | G27: ='表 1‑21'!C3 -> ➖ | H27: ='表 1‑21'!C4 -> ➖ | I27: ='表 1‑21'!C5 -> ➖ | J27: ='表 1‑21'!C6 -> ➖ | K27: ='表 1‑21'!C7 -> ➖ | L27: ='表 1‑21'!C8 -> ➖ | M27: ='表 1‑21'!C9 -> ➖ | P27: 0~19坪 | Q27: 20~29坪 | R27: 30~39坪 | S27: 40~49坪 | T27: 50~59坪 | U27: 60~69坪 | V27: 70坪以上 | W27: 總計
C28: 22 | D28: 表 1‑22 | E28: 建物所有權登記原因－按住宅使用狀況分 | F28: 查看 | G28: ='表 1‑22'!C3 -> ➖ | H28: ='表 1‑22'!C4 -> ➖ | I28: ='表 1‑22'!C5 -> ➖ | J28: ='表 1‑22'!C6 -> ➖ | K28: ='表 1‑22'!C7 -> ➖ | L28: ='表 1‑22'!C8 -> ➖ | M28: ='表 1‑22'!C9 -> ➖ | O28: 連江縣 | P28: -0.17415141 | Q28: -2.6486679 | R28: 4.7318045 | S28: 8.6691008 | T28: -1.3280197 | U28: -1.656742 | V28: -7.5933242 | W28: 0
C29: 23 | D29: 表 1‑23 | E29: 建物所有權登記原因－按地區分 | F29: 查看 | G29: ='表 1‑23'!C3 -> ➖ | H29: ='表 1‑23'!C4 -> ➖ | I29: ='表 1‑23'!C5 -> ➖ | J29: ='表 1‑23'!C6 -> ➖ | K29: ='表 1‑23'!C7 -> ➖ | L29: ='表 1‑23'!C8 -> ➖ | M29: ='表 1‑23'!C9 -> ➖ | O29: 總計 | P29: 0.27252627 | Q29: 0.065366335 | R29: -0.2122703 | S29: -0.07052751 | T29: -0.018230787 | U29: -0.023488875 | V29: -0.013375131 | W29: 0
C30: 24 | D30: 表 1‑24 | E30: 建物所有權登記原因－按建物屋齡分 | F30: 查看 | G30: ='表 1‑24'!C3 -> ➖ | H30: ='表 1‑24'!C4 -> ➖ | I30: ='表 1‑24'!C5 -> ➖ | J30: ='表 1‑24'!C6 -> ➖ | K30: ='表 1‑24'!C7 -> ➖ | L30: ='表 1‑24'!C8 -> ➖ | M30: ='表 1‑24'!C9 -> ➖
C31: 25 | D31: 表 1‑25 | E31: 建物所有權登記原因－按建物面積(坪)分 | F31: 查看 | G31: ='表 1‑25'!C3 -> ➖ | H31: ='表 1‑25'!C4 -> ➖ | I31: ='表 1‑25'!C5 -> ➖ | J31: ='表 1‑25'!C6 -> ➖ | K31: ='表 1‑25'!C7 -> ➖ | L31: ='表 1‑25'!C8 -> ➖ | M31: ='表 1‑25'!C9 -> ➖ | P31: 1~5樓 | Q31: 6~10樓 | R31: 11~15樓 | S31: 16~20樓 | T31: 21樓以上 | U31: 總計
C32: 26 | D32: 表 1‑26 | E32: 建物所有權登記原因－按建物總樓層分 | F32: 查看 | G32: ='表 1‑26'!C3 -> ➖ | H32: ='表 1‑26'!C4 -> ➖ | I32: ='表 1‑26'!C5 -> ➖ | J32: ='表 1‑26'!C6 -> ➖ | K32: ='表 1‑26'!C7 -> ➖ | L32: ='表 1‑26'!C8 -> ➖ | M32: ='表 1‑26'!C9 -> ➖ | O32: 連江縣 | P32: 69.712794 | Q32: 24.543081 | R32: 5.7441253 | S32: 0 | T32: 0 | U32: 100
C33: 27 | D33: 表 1‑27 | E33: 建物所有權登記原因－按建物使用類別分 | F33: 查看 | G33: ='表 1‑27'!C3 -> ➖ | H33: ='表 1‑27'!C4 -> ➖ | I33: ='表 1‑27'!C5 -> ➖ | J33: ='表 1‑27'!C6 -> ➖ | K33: ='表 1‑27'!C7 -> ➖ | L33: ='表 1‑27'!C8 -> ➖ | M33: ='表 1‑27'!C9 -> ➖ | O33: 總計 | P33: 59.552049 | Q33: 13.823499 | R33: 18.076715 | S33: 4.2542576 | T33: 4.2934799 | U33: 100
C34: 28 | D34: 表 1‑28 | E34: 建物所有權登記原因－按建物結構分 | F34: 查看 | G34: ='表 1‑28'!C3 -> ➖ | H34: ='表 1‑28'!C4 -> ➖ | I34: ='表 1‑28'!C5 -> ➖ | J34: ='表 1‑28'!C6 -> ➖ | K34: ='表 1‑28'!C7 -> ➖ | L34: ='表 1‑28'!C8 -> ➖ | M34: ='表 1‑28'!C9 -> ➖ | P34: 1~5樓 | Q34: 6~10樓 | R34: 11~15樓 | S34: 16~20樓 | T34: 21樓以上 | U34: 總計
C35: 29 | D35: 表 1‑29 | E35: 建物所有權登記原因－按住宅使用狀況與地區分 | F35: 查看 | G35: ='表 1‑29'!C3 -> ➖ | H35: ='表 1‑29'!C4 -> ➖ | I35: ='表 1‑29'!C5 -> ➖ | J35: ='表 1‑29'!C6 -> ➖ | K35: ='表 1‑29'!C7 -> ➖ | L35: ='表 1‑29'!C8 -> ➖ | M35: ='表 1‑29'!C9 -> ➖ | O35: 連江縣 | P35: -27.103686 | Q35: 21.35956 | R35: 5.7441253 | S35: 0 | T35: 0 | U35: 0
C36: 30 | D36: 表 1‑30 | E36: 建物所有權登記原因－按住宅使用狀況與建物屋齡分 | F36: 查看 | G36: ='表 1‑30'!C3 -> ➖ | H36: ='表 1‑30'!C4 -> ➖ | I36: ='表 1‑30'!C5 -> ➖ | J36: ='表 1‑30'!C6 -> ➖ | K36: ='表 1‑30'!C7 -> ➖ | L36: ='表 1‑30'!C8 -> ➖ | M36: ='表 1‑30'!C9 -> ➖ | O36: 總計 | P36: -0.50125465 | Q36: -0.047784567 | R36: 0.32117277 | S36: 0.039177654 | T36: 0.18868879 | U36: 0
C37: 31 | D37: 表 1‑31 | E37: 建物所有權登記原因－按住宅使用狀況與建物面積(坪)分 | F37: 查看 | G37: ='表 1‑31'!C3 -> ➖ | H37: ='表 1‑31'!C4 -> ➖ | I37: ='表 1‑31'!C5 -> ➖ | J37: ='表 1‑31'!C6 -> ➖ | K37: ='表 1‑31'!C7 -> ➖ | L37: ='表 1‑31'!C8 -> ➖ | M37: ='表 1‑31'!C9 -> ➖
C38: 32 | D38: 表 1‑32 | E38: 建物所有權登記原因－按住宅使用狀況與建物總樓層分 | F38: 查看 | G38: ='表 1‑32'!C3 -> ➖ | H38: ='表 1‑32'!C4 -> ➖ | I38: ='表 1‑32'!C5 -> ➖ | J38: ='表 1‑32'!C6 -> ➖ | K38: ='表 1‑32'!C7 -> ➖ | L38: ='表 1‑32'!C8 -> ➖ | M38: ='表 1‑32'!C9 -> ➖ | P38: 住家用 | Q38: 住商用 | R38: 住工用 | S38: 國民住宅 | T38: 其他 | U38: 總計
C39: 33 | D39: 表 1‑33 | E39: 建物所有權登記原因－按住宅使用狀況與建物使用類別分 | F39: 查看 | G39: ='表 1‑33'!C3 -> ➖ | H39: ='表 1‑33'!C4 -> ➖ | I39: ='表 1‑33'!C5 -> ➖ | J39: ='表 1‑33'!C6 -> ➖ | K39: ='表 1‑33'!C7 -> ➖ | L39: ='表 1‑33'!C8 -> ➖ | M39: ='表 1‑33'!C9 -> ➖ | O39: 連江縣 | P39: 20.509554 | Q39: 1.1464968 | R39: 0 | S39: 0 | T39: 78.343949 | U39: 100
C40: 34 | D40: 表 1‑34 | E40: 建物所有權登記原因－按住宅使用狀況與建物結構分 | F40: 查看 | G40: ='表 1‑34'!C3 -> ➖ | H40: ='表 1‑34'!C4 -> ➖ | I40: ='表 1‑34'!C5 -> ➖ | J40: ='表 1‑34'!C6 -> ➖ | K40: ='表 1‑34'!C7 -> ➖ | L40: ='表 1‑34'!C8 -> ➖ | M40: ='表 1‑34'!C9 -> ➖ | O40: 總計 | P40: 57.975341 | Q40: 7.2337552 | R40: 0.15811355 | S40: 0.32592718 | T40: 34.306863 | U40: 100
C41: 35 | D41: 表 2‑1 | E41: 宅內人口數－按地區分 | F41: 查看 | G41: ='表 2‑1'!C3 -> ➖ | H41: ='表 2‑1'!C4 -> ➖ | I41: ='表 2‑1'!C5 -> ➖ | J41: ='表 2‑1'!C6 -> ➖ | K41: ='表 2‑1'!C7 -> ➖ | L41: ='表 2‑1'!C8 -> ➖ | M41: ='表 2‑1'!C9 -> ➖ | P41: 住家用 | Q41: 住商用 | R41: 住工用 | S41: 國民住宅 | T41: 其他 | U41: 總計
C42: 36 | D42: 表 2‑2 | E42: 宅內人口數－按建物屋齡分 | F42: 查看 | G42: ='表 2‑2'!C3 -> ➖ | H42: ='表 2‑2'!C4 -> ➖ | I42: ='表 2‑2'!C5 -> ➖ | J42: ='表 2‑2'!C6 -> ➖ | K42: ='表 2‑2'!C7 -> ➖ | L42: ='表 2‑2'!C8 -> ➖ | M42: ='表 2‑2'!C9 -> ➖ | O42: 連江縣 | P42: -8.2427063 | Q42: -0.48098962 | R42: 0 | S42: 0 | T42: 8.7236959 | U42: 0
C43: 37 | D43: 表 2‑3 | E43: 宅內人口數－按建物面積(坪)分 | F43: 查看 | G43: ='表 2‑3'!C3 -> ➖ | H43: ='表 2‑3'!C4 -> ➖ | I43: ='表 2‑3'!C5 -> ➖ | J43: ='表 2‑3'!C6 -> ➖ | K43: ='表 2‑3'!C7 -> ➖ | L43: ='表 2‑3'!C8 -> ➖ | M43: ='表 2‑3'!C9 -> ➖ | O43: 總計 | P43: -0.81483786 | Q43: -0.12010618 | R43: -0.0028647488 | S43: -0.047303406 | T43: 0.9851122 | U43: 0
C44: 38 | D44: 表 2‑4 | E44: 宅內人口數－按建物總樓層分 | F44: 查看 | G44: ='表 2‑4'!C3 -> ➖ | H44: ='表 2‑4'!C4 -> ➖ | I44: ='表 2‑4'!C5 -> ➖ | J44: ='表 2‑4'!C6 -> ➖ | K44: ='表 2‑4'!C7 -> ➖ | L44: ='表 2‑4'!C8 -> ➖ | M44: ='表 2‑4'!C9 -> ➖
...

Sheet 首頁_屋齡
C3: 資料匯出報表目錄
H5: 2024年
C6: 序號 | D6: 表索引 | E6: 描述 | F6: 連結
C7: 1 | D7: 表 1‑1 | E7: 全國住宅使用現況－按地區分 | F7: 查看
C8: 2 | D8: 表 1‑2 | E8: 全國住宅使用現況－按建物總樓層分 | F8: 查看
C9: 3 | D9: 表 1‑3 | E9: 全國住宅使用現況－按建物屋齡分 | F9: 查看
C10: 4 | D10: 表 1‑4 | E10: 全國住宅使用現況－按建物面積分 | F10: 查看
C11: 5 | D11: 表 1‑5 | E11: 全國住宅使用現況－按建物使用類別分 | F11: 查看
C12: 6 | D12: 表 1‑6 | E12: 全國住宅使用現況－按建物結構分 | F12: 查看
C13: 7 | D13: 表 1‑7 | E13: 各地區住宅分布－按建物屋齡分 | F13: 查看
C14: 8 | D14: 表 1‑8 | E14: 各地區住宅分布－按建物面積（坪）分 | F14: 查看
C15: 9 | D15: 表 1‑9 | E15: 各地區住宅分布－按建物總樓層分 | F15: 查看
C16: 10 | D16: 表 1‑10 | E16: 各地區住宅分布－按建物使用類別分 | F16: 查看
C17: 11 | D17: 表 1‑11 | E17: 各地區住宅分布－按建物結構分 | F17: 查看
C18: 12 | D18: 表 1‑12 | E18: 各建物屋齡分布－按建物面積（坪）分 | F18: 查看
... C31: 25 | D31: 表 1‑25 | E31: 建物所有權登記原因－按建物面積(坪)分 | F31: 查看
C32: 26 | D32: 表 1‑26 | E32: 建物所有權登記原因－按建物總樓層分 | F32: 查看 | H32: 2024年
C33: 27 | D33: 表 1‑27 | E33: 建物所有權登記原因－按建物使用類別分 | F33: 查看
C34: 28 | D34: 表 1‑28 | E34: 建物所有權登記原因－按建物結構分 | F34: 查看
C35: 29 | D35: 表 1‑29 | E35: 建物所有權登記原因－按住宅使用狀況與地區分 | F35: 查看
C36: 30 | D36: 表 1‑30 | E36: 建物所有權登記原因－按住宅使用狀況與建物屋齡分 | F36: 查看
C37: 31 | D37: 表 1‑31 | E37: 建物所有權登記原因－按住宅使用狀況與建物面積(坪)分 | F37: 查看
C38: 32 | D38: 表 1‑32 | E38: 建物所有權登記原因－按住宅使用狀況與建物總樓層分 | F38: 查看
C39: 33 | D39: 表 1‑33 | E39: 建物所有權登記原因－按住宅使用狀況與建物使用類別分 | F39: 查看
C40: 34 | D40: 表 1‑34 | E40: 建物所有權登記原因－按住宅使用狀況與建物結構分 | F40: 查看
C41: 35 | D41: 表 2‑1 | E41: 宅內人口數－按地區分 | F41: 查看
C42: 36 | D42: 表 2‑2 | E42: 宅內人口數－按建物屋齡分 | F42: 查看
C43: 37 | D43: 表 2‑3 | E43: 宅內人口數－按建物面積(坪)分 | F43: 查看
C44: 38 | D44: 表 2‑4 | E44: 宅內人口數－按建物總樓層分 | F44: 查看 | H44: 2024年
C45: 39 | D45: 表 2‑5 | E45: 宅內人口數－按住宅使用狀況分 | F45: 查看
C46: 40 | D46: 表 2‑6 | E46: 宅內人口數－按建物使用類別分 | F46: 查看
C47: 41 | D47: 表 2‑7 | E47: 宅內人口數－按建物結構分 | F47: 查看
C48: 42 | D48: 表 2‑8 | E48: 合住情形－按建物屋齡分 | F48: 查看
C49: 43 | D49: 表 2‑9 | E49: 合住情形－按建物面積(坪)分 | F49: 查看
C50: 44 | D50: 表 2‑10 | E50: 合住情形－按建物總樓層分 | F50: 查看
C51: 45 | D51: 表 2‑11 | E51: 合住情形－按住宅使用狀況分 | F51: 查看
C52: 46 | D52: 表 2‑12 | E52: 合住情形－按建物使用類別分 | F52: 查看
C53: 47 | D53: 表 2‑13 | E53: 合住情形－按結構分 | F53: 查看
C54: 48 | D54: 表 2‑14 | E54: 家戶類別－按地區分 | F54: 查看
C55: 49 | D55: 表 2‑15 | E55: 家戶類別－按建物屋齡分 | F55: 查看
...

Sheet 首頁_所有權
C3: 資料匯出報表目錄
C6: 序號 | D6: 表索引 | E6: 描述 | F6: 連結
C7: 1 | D7: 表 1‑1 | E7: 全國住宅使用現況－按地區分 | F7: 查看
C8: 2 | D8: 表 1‑2 | E8: 全國住宅使用現況－按建物總樓層分 | F8: 查看
C9: 3 | D9: 表 1‑3 | E9: 全國住宅使用現況－按建物屋齡分 | F9: 查看
C10: 4 | D10: 表 1‑4 | E10: 全國住宅使用現況－按建物面積分 | F10: 查看
C11: 5 | D11: 表 1‑5 | E11: 全國住宅使用現況－按建物使用類別分 | F11: 查看
C12: 6 | D12: 表 1‑6 | E12: 全國住宅使用現況－按建物結構分 | F12: 查看
C13: 7 | D13: 表 1‑7 | E13: 各地區住宅分布－按建物屋齡分 | F13: 查看
C14: 8 | D14: 表 1‑8 | E14: 各地區住宅分布－按建物面積（坪）分 | F14: 查看
C15: 9 | D15: 表 1‑9 | E15: 各地區住宅分布－按建物總樓層分 | F15: 查看
C16: 10 | D16: 表 1‑10 | E16: 各地區住宅分布－按建物使用類別分 | F16: 查看
C17: 11 | D17: 表 1‑11 | E17: 各地區住宅分布－按建物結構分 | F17: 查看
C18: 12 | D18: 表 1‑12 | E18: 各建物屋齡分布－按建物面積（坪）分 | F18: 查看
... C71: 65 | D71: 表 2‑32 | E71: 戶內擁屋數量－按家戶人口分 | F71: 查看

Sheet 首頁_模板
C3: 資料匯出報表目錄
C6: 序號 | D6: 表索引 | E6: 描述 | F6: 連結
C7: 1 | D7: 表 1‑1 | E7: 全國住宅使用現況－按地區分 | F7: 查看
C8: 2 | D8: 表 1‑2 | E8: 全國住宅使用現況－按建物總樓層分 | F8: 查看
C9: 3 | D9: 表 1‑3 | E9: 全國住宅使用現況－按建物屋齡分 | F9: 查看
C10: 4 | D10: 表 1‑4 | E10: 全國住宅使用現況－按建物面積分 | F10: 查看
C11: 5 | D11: 表 1‑5 | E11: 全國住宅使用現況－按建物使用類別分 | F11: 查看
C12: 6 | D12: 表 1‑6 | E12: 全國住宅使用現況－按建物結構分 | F12: 查看
C13: 7 | D13: 表 1‑7 | E13: 各地區住宅分布－按建物屋齡分 | F13: 查看
C14: 8 | D14: 表 1‑8 | E14: 各地區住宅分布－按建物面積（坪）分 | F14: 查看
C15: 9 | D15: 表 1‑9 | E15: 各地區住宅分布－按建物總樓層分 | F15: 查看
C16: 10 | D16: 表 1‑10 | E16: 各地區住宅分布－按建物使用類別分 | F16: 查看
C17: 11 | D17: 表 1‑11 | E17: 各地區住宅分布－按建物結構分 | F17: 查看
C18: 12 | D18: 表 1‑12 | E18: 各建物屋齡分布－按建物面積（坪）分 | F18: 查看
... C71: 65 | D71: 表 2‑32 | E71: 戶內擁屋數量－按家戶人口分 | F71: 查看

Sheet 表 1‑1
A1: 🏠
B2: 人員 | C2: 到此一遊 | E2: 2024年 | F2: 全國住宅使用現況－按地區分 | K2: YOY | L2: 全國住宅使用現況－按地區分 | Q2: 2023年 | R2: 全國住宅使用現況－按地區分 | W2: YOY | X2: 全國住宅使用現況－按地區分 | AC2: 2022年 | AD2: 全國住宅使用現況－按地區分 | AI2: YOY | AJ2: 全國住宅使用現況－按地區分 | AO2: 2021年 | AP2: 全國住宅使用現況－按地區分 | AS2: YOY | AT2: 全國住宅使用現況－按地區分 | AW2: 2020年 | AX2: 全國住宅使用現況－按地區分
A3: ➡ | B3: 宥婕 | C3: ➖ | F3: 低度用電 | G3: 非低度用電 | H3: 資料缺失 | I3: 總計 | L3: 低度用電 | M3: 非低度用電 | N3: 資料缺失 | O3: 總計 | R3: 低度用電 | S3: 非低度用電 | T3: 資料缺失 | U3: 總計 | X3: 低度用電 | Y3: 非低度用電 | Z3: 資料缺失 | AA3: 總計 | AD3: 低度用電 | AE3: 非低度用電 | AF3: 資料缺失 | AG3: 總計 | AJ3: 低度用電 | AK3: 非低度用電 | AL3: 資料缺失 | AM3: 總計 | AP3: 資料缺失 | AQ3: 總計 | AT3: 資料缺失 | AU3: 總計 | AX3: 資料缺失 | AY3: 總計
B4: 瀚平 | C4: ➖ | E4: 臺北市 | F4: 53573 | G4: 749949 | H4: 333123 | I4: 1136645 | K4: 臺北市 | L4: -657 | M4: -21356 | N4: 27799 | O4: 5786 | Q4: 臺北市 | R4: 54230 | S4: 771305 | T4: 305324 | U4: 1130859 | W4: 臺北市 | X4: -83 | Y4: 18307 | Z4: -12770 | AA4: 5454 | AC4: 臺北市 | AD4: 54313 | AE4: 752998 | AF4: 318094 | AG4: 1125405 | AI4: 臺北市 | AJ4: 54313 | AK4: 752998 | AL4: -803444 | AM4: 3867 | AO4: 臺北市 | AP4: 1121538 | AQ4: 1121538 | AS4: 臺北市 | AT4: 46774 | AU4: 46774 | AW4: 臺北市 | AX4: 1074764 | AY4: 1074764
B5: 賀翔 | C5: ➖ | E5: 新北市 | F5: 106240 | G5: 1439483 | H5: 336044 | I5: 1881767 | K5: 新北市 | L5: 5593 | M5: 18099 | N5: -2187 | O5: 21505 | Q5: 新北市 | R5: 100647 | S5: 1421384 | T5: 338231 | U5: 1860262 | W5: 新北市 | X5: -3501 | Y5: 21469 | Z5: 1967 | AA5: 19935 | AC5: 新北市 | AD5: 104148 | AE5: 1399915 | AF5: 336264 | AG5: 1840327 | AI5: 新北市 | AJ5: 104148 | AK5: 1399915 | AL5: -1485052 | AM5: 19011 | AO5: 新北市 | AP5: 1821316 | AQ5: 1821316 | AS5: 新北市 | AT5: 59000 | AU5: 59000 | AW5: 新北市 | AX5: 1762316 | AY5: 1762316
B6: 尚書 | C6: ➖ | E6: 桃園市 | F6: 64487 | G6: 662789 | H6: 227574 | I6: 954850 | K6: 桃園市 | L6: 4846 | M6: 15043 | N6: 2674 | O6: 22563 | Q6: 桃園市 | R6: 59641 | S6: 647746 | T6: 224900 | U6: 932287 | W6: 桃園市 | X6: -3393 | Y6: 19915 | Z6: 1708 | AA6: 18230 | AC6: 桃園市 | AD6: 63034 | AE6: 627831 | AF6: 223192 | AG6: 914057 | AI6: 桃園市 | AJ6: 63034 | AK6: 627831 | AL6: -671724 | AM6: 19141 | AO6: 桃園市 | AP6: 894916 | AQ6: 894916 | AS6: 桃園市 | AT6: 36219 | AU6: 36219 | AW6: 桃園市 | AX6: 858697 | AY6: 858697
B7: 文琪 | C7: ➖ | E7: 臺中市 | F7: 73878 | G7: 771660 | H7: 305202 | I7: 1150740 | K7: 臺中市 | L7: 7340 | M7: 22013 | N7: -2581 | O7: 26772 | Q7: 臺中市 | R7: 66538 | S7: 749647 | T7: 307783 | U7: 1123968 | W7: 臺中市 | X7: -3773 | Y7: 12274 | Z7: 12695 | AA7: 21196 | AC7: 臺中市 | AD7: 70311 | AE7: 737373 | AF7: 295088 | AG7: 1102772 | AI7: 臺中市 | AJ7: 70311 | AK7: 737373 | AL7: -784982 | AM7: 22702 | AO7: 臺中市 | AP7: 1080070 | AQ7: 1080070 | AS7: 臺中市 | AT7: 33448 | AU7: 33448 | AW7: 臺中市 | AX7: 1046622 | AY7: 1046622
B8: 育誠 | C8: ➖ | E8: 臺南市 | F8: 48151 | G8: 440406 | H8: 200773 | I8: 689330 | K8: 臺南市 | L8: 6278 | M8: 12243 | N8: -2429 | O8: 16092 | Q8: 臺南市 | R8: 41873 | S8: 428163 | T8: 203202 | U8: 673238 | W8: 臺南市 | X8: 868 | Y8: 6481 | Z8: 5150 | AA8: 12499 | AC8: 臺南市 | AD8: 41005 | AE8: 421682 | AF8: 198052 | AG8: 660739 | AI8: 臺南市 | AJ8: 41005 | AK8: 421682 | AL8: -451470 | AM8: 11217 | AO8: 臺南市 | AP8: 649522 | AQ8: 649522 | AS8: 臺南市 | AT8: 18135 | AU8: 18135 | AW8: 臺南市 | AX8: 631387 | AY8: 631387
B9: 會議 | C9: ➖ | E9: 高雄市 | F9: 90649 | G9: 787272 | H9: 208002 | I9: 1085923 | K9: 高雄市 | L9: 6550 | M9: 16896 | N9: -6386 | O9: 17060 | Q9: 高雄市 | R9: 84099 | S9: 770376 | T9: 214388 | U9: 1068863 | W9: 高雄市 | X9: 449 | Y9: 9631 | Z9: 6849 | AA9: 16929 | AC9: 高雄市 | AD9: 83650 | AE9: 760745 | AF9: 207539 | AG9: 1051934 | AI9: 高雄市 | AJ9: 83650 | AK9: 760745 | AL9: -829076 | AM9: 15319 | AO9: 高雄市 | AP9: 1036615 | AQ9: 1036615 | AS9: 高雄市 | AT9: 24090 | AU9: 24090 | AW9: 高雄市 | AX9: 1012525 | AY9: 1012525
E10: 基隆市 | F10: 14703 | G10: 118686 | H10: 43224 | I10: 176613 | K10: 基隆市 | L10: 25 | M10: 386 | N10: 1284 | O10: 1695 | Q10: 基隆市 | R10: 14678 | S10: 118300 | T10: 41940 | U10: 174918 | W10: 基隆市 | X10: 434 | Y10: 2124 | Z10: -1024 | AA10: 1534 | AC10: 基隆市 | AD10: 14244 | AE10: 116176 | AF10: 42964 | AG10: 173384 | AI10: 基隆市 | AJ10: 14244 | AK10: 116176 | AL10: -129249 | AM10: 1171 | AO10: 基隆市 | AP10: 172213 | AQ10: 172213 | AS10: 基隆市 | AT10: 5938 | AU10: 5938 | AW10: 基隆市 | AX10: 166275 | AY10: 166275
E11: 新竹市 | F11: 11053 | G11: 131130 | H11: 53825 | I11: 196008 | K11: 新竹市 | L11: 565 | M11: 2449 | N11: 202 | O11: 3216 | Q11: 新竹市 | R11: 10488 | S11: 128681 | T11: 53623 | U11: 192792 | W11: 新竹市 | X11: -505 | Y11: 2545 | Z11: 957 | AA11: 2997 | AC11: 新竹市 | AD11: 10993 | AE11: 126136 | AF11: 52666 | AG11: 189795 | AI11: 新竹市 | AJ11: 10993 | AK11: 126136 | AL11: -135338 | AM11: 1791 | AO11: 新竹市 | AP11: 188004 | AQ11: 188004 | AS11: 新竹市 | AT11: 9634 | AU11: 9634 | AW11: 新竹市 | AX11: 178370 | AY11: 178370
E12: 新竹縣 | F12: 11358 | G12: 125143 | H12: 84101 | I12: 220602 | K12: 新竹縣 | L12: 1266 | M12: 4425 | N12: 474 | O12: 6165 | Q12: 新竹縣 | R12: 10092 | S12: 120718 | T12: 83627 | U12: 214437 | W12: 新竹縣 | X12: -644 | Y12: 2315 | Z12: 4271 | AA12: 5942 | AC12: 新竹縣 | AD12: 10736 | AE12: 118403 | AF12: 79356 | AG12: 208495 | AI12: 新竹縣 | AJ12: 10736 | AK12: 118403 | AL12: -124296 | AM12: 4843 | AO12: 新竹縣 | AP12: 203652 | AQ12: 203652 | AS12: 新竹縣 | AT12: 10240 | AU12: 10240 | AW12: 新竹縣 | AX12: 193412 | AY12: 193412
E13: 宜蘭縣 | F13: 20470 | G13: 123382 | H13: 40665 | I13: 184517 | K13: 宜蘭縣 | L13: 1081 | M13: 5492 | N13: -3430 | O13: 3143 | Q13: 宜蘭縣 | R13: 19389 | S13: 117890 | T13: 44095 | U13: 181374 | W13: 宜蘭縣 | X13: -489 | Y13: 927 | Z13: 2785 | AA13: 3223 | AC13: 宜蘭縣 | AD13: 19878 | AE13: 116963 | AF13: 41310 | AG13: 178151 | AI13: 宜蘭縣 | AJ13: 19878 | AK13: 116963 | AL13: -134129 | AM13: 2712 | AO13: 宜蘭縣 | AP13: 175439 | AQ13: 175439 | AS13: 宜蘭縣 | AT13: 6518 | AU13: 6518 | AW13: 宜蘭縣 | AX13: 168921 | AY13: 168921
E14: 苗栗縣 | F14: 12566 | G14: 105322 | H14: 59443 | I14: 177331 | K14: 苗栗縣 | L14: 879 | M14: 6171 | N14: -3874 | O14: 3176 | Q14: 苗栗縣 | R14: 11687 | S14: 99151 | T14: 63317 | U14: 174155 | W14: 苗栗縣 | X14: -114 | Y14: 1372 | Z14: 1686 | AA14: 2944 | AC14: 苗栗縣 | AD14: 11801 | AE14: 97779 | AF14: 61631 | AG14: 171211 | AI14: 苗栗縣 | AJ14: 11801 | AK14: 97779 | AL14: -101949 | AM14: 7631 | AO14: 苗栗縣 | AP14: 163580 | AQ14: 163580 | AS14: 苗栗縣 | AT14: 74 | AU14: 74 | AW14: 苗栗縣 | AX14: 163506 | AY14: 163506
E15: 彰化縣 | F15: 22000 | G15: 201857 | H15: 88769 | I15: 312626 | K15: 彰化縣 | L15: 2135 | M15: 11906 | N15: -7691 | O15: 6350 | Q15: 彰化縣 | R15: 19865 | S15: 189951 | T15: 96460 | U15: 306276 | W15: 彰化縣 | X15: -1103 | Y15: -873 | Z15: 6770 | AA15: 4794 | AC15: 彰化縣 | AD15: 20968 | AE15: 190824 | AF15: 89690 | AG15: 301482 | AI15: 彰化縣 | AJ15: 20968 | AK15: 190824 | AL15: -206488 | AM15: 5304 | AO15: 彰化縣 | AP15: 296178 | AQ15: 296178 | AS15: 彰化縣 | AT15: 5909 | AU15: 5909 | AW15: 彰化縣 | AX15: 290269 | AY15: 290269
E16: 南投縣 | F16: 10169 | G16: 82388 | H16: 38243 | I16: 130800 | K16: 南投縣 | L16: 997 | M16: 2182 | N16: -1273 | O16: 1906 | Q16: 南投縣 | R16: 9172 | S16: 80206 | T16: 39516 | U16: 128894 | W16: 南投縣 | X16: -530 | Y16: 1021 | Z16: 1555 | AA16: 2046 | AC16: 南投縣 | AD16: 9702 | AE16: 79185 | AF16: 37961 | AG16: 126848 | AI16: 南投縣 | AJ16: 9702 | AK16: 79185 | AL16: -87048 | AM16: 1839 | AO16: 南投縣 | AP16: 125009 | AQ16: 125009 | AS16: 南投縣 | AT16: 2192 | AU16: 2192 | AW16: 南投縣 | AX16: 122817 | AY16: 122817
E17: 雲林縣 | F17: 12664 | G17: 96035 | H17: 53951 | I17: 162650 | K17: 雲林縣 | L17: 2158 | M17: 7701 | N17: -5932 | O17: 3927 | Q17: 雲林縣 | R17: 10506 | S17: 88334 | T17: 59883 | U17: 158723 | W17: 雲林縣 | X17: -633 | Y17: -808 | Z17: 5122 | AA17: 3681 | AC17: 雲林縣 | AD17: 11139 | AE17: 89142 | AF17: 54761 | AG17: 155042 | AI17: 雲林縣 | AJ17: 11139 | AK17: 89142 | AL17: -97207 | AM17: 3074 | AO17: 雲林縣 | AP17: 151968 | AQ17: 151968 | AS17: 雲林縣 | AT17: 4021 | AU17: 4021 | AW17: 雲林縣 | AX17: 147947 | AY17: 147947
E18: 嘉義市 | F18: 8782 | G18: 69550 | H18: 30946 | I18: 109278 | K18: 嘉義市 | L18: 2655 | M18: 15748 | N18: -17161 | O18: 1242 | Q18: 嘉義市 | R18: 6127 | S18: 53802 | T18: 48107 | U18: 108036 | W18: 嘉義市 | X18: 43 | Y18: 2214 | Z18: -1522 | AA18: 735 | AC18: 嘉義市 | AD18: 6084 | AE18: 51588 | AF18: 49629 | AG18: 107301 | AI18: 嘉義市 | AJ18: 6084 | AK18: 51588 | AL18: -56872 | AM18: 800 | AO18: 嘉義市 | AP18: 106501 | AQ18: 106501 | AS18: 嘉義市 | AT18: 2786 | AU18: 2786 | AW18: 嘉義市 | AX18: 103715 | AY18: 103715
E19: 嘉義縣 | F19: 8027 | G19: 63714 | H19: 49317 | I19: 121058 | K19: 嘉義縣 | L19: 1592 | M19: 9338 | N19: -9278 | O19: 1652 | Q19: 嘉義縣 | R19: 6435 | S19: 54376 | T19: 58595 | U19: 119406 | W19: 嘉義縣 | X19: -754 | Y19: -2681 | Z19: 5721 | AA19: 2286 | AC19: 嘉義縣 | AD19: 7189 | AE19: 57057 | AF19: 52874 | AG19: 117120 | AI19: 嘉義縣 | AJ19: 7189 | AK19: 57057 | AL19: -62823 | AM19: 1423 | AO19: 嘉義縣 | AP19: 115697 | AQ19: 115697 | AS19: 嘉義縣 | AT19: 2313 | AU19: 2313 | AW19: 嘉義縣 | AX19: 113384 | AY19: 113384
E20: 屏東縣 | F20: 16853 | G20: 142076 | H20: 59147 | I20: 218076 | K20: 屏東縣 | L20: 1830 | M20: 5476 | N20: -3611 | O20: 3695 | Q20: 屏東縣 | R20: 15023 | S20: 136600 | T20: 62758 | U20: 214381 | W20: 屏東縣 | X20: 23 | Y20: 1627 | Z20: 2140 | AA20: 3790 | AC20: 屏東縣 | AD20: 15000 | AE20: 134973 | AF20: 60618 | AG20: 210591 | AI20: 屏東縣 | AJ20: 15000 | AK20: 134973 | AL20: -146691 | AM20: 3282 | AO20: 屏東縣 | AP20: 207309 | AQ20: 207309 | AS20: 屏東縣 | AT20: 3607 | AU20: 3607 | AW20: 屏東縣 | AX20: 203702 | AY20: 203702
E21: 澎湖縣 | F21: 1251 | G21: 11541 | H21: 17302 | I21: 30094 | K21: 澎湖縣 | L21: 263 | M21: 1059 | N21: -982 | O21: 340 | Q21: 澎湖縣 | R21: 988 | S21: 10482 | T21: 18284 | U21: 29754 | W21: 澎湖縣 | X21: -36 | Y21: 9 | Z21: 529 | AA21: 502 | AC21: 澎湖縣 | AD21: 1024 | AE21: 10473 | AF21: 17755 | AG21: 29252 | AI21: 澎湖縣 | AJ21: 1024 | AK21: 10473 | AL21: -11040 | AM21: 457 | AO21: 澎湖縣 | AP21: 28795 | AQ21: 28795 | AS21: 澎湖縣 | AT21: 620 | AU21: 620 | AW21: 澎湖縣 | AX21: 28175 | AY21: 28175
... E26: 總計 | F26: 604312 | G26: 6245790 | H26: 2283840 | I26: 9133942 | K26: 總計 | L26: 47385 | M26: 137895 | N26: -36400 | O26: 148880 | Q26: 總計 | R26: 556927 | S26: 6107895 | T26: 2320240 | U26: 8985062 | W26: 總計 | X26: -14004 | Y26: 98342 | Z26: 47120 | AA26: 131458 | AC26: 總計 | AD26: 570931 | AE26: 6009553 | AF26: 2273120 | AG26: 8853604 | AI26: 總計 | AJ26: 570931 | AK26: 6009553 | AL26: -6452666 | AM26: 127818 | AO26: 總計 | AP26: 8725786 | AQ26: 8725786 | AS26: 總計 | AT26: 278189 | AU26: 278189 | AW26: 總計 | AX26: 8447597 | AY26: 8447597
F28: 低度用電 | G28: 非低度用電 | H28: 總計 | L28: 低度用電 | M28: 非低度用電 | N28: 總計 | R28: 低度用電 | S28: 非低度用電 | T28: 總計 | X28: 低度用電 | Y28: 非低度用電 | Z28: 總計 | AD28: 低度用電 | AE28: 非低度用電 | AF28: 總計 | AJ28: 低度用電 | AK28: 非低度用電 | AL28: 總計 | AP28: 總計 | AT28: 總計 | AX28: 總計
E29: 臺北市 | F29: 6.6672723 | G29: 93.332728 | H29: 100 | K29: 臺北市 | L29: 0.098198945 | M29: -0.098198945 | N29: 0 | Q29: 臺北市 | R29: 6.5690734 | S29: 93.430927 | T29: 100 | W29: 臺北市 | X29: -0.15856937 | Y29: 0.15856937 | Z29: 0 | AC29: 臺北市 | AD29: 6.7276428 | AE29: 93.272357 | AF29: 100 | AI29: 臺北市 | AJ29: 6.7276428 | AK29: 93.272357 | AL29: 100 | AO29: 臺北市 | AP29: 0 | AS29: 臺北市 | AT29: 0 | AW29: 臺北市 | AX29: 0
E30: 新北市 | F30: 6.873159 | G30: 93.126841 | H30: 100 | K30: 新北市 | L30: 0.26048163 | M30: -0.26048163 | N30: 0 | Q30: 新北市 | R30: 6.6126774 | S30: 93.387323 | T30: 100 | W30: 新北市 | X30: -0.31176659 | Y30: 0.31176659 | Z30: 0 | AC30: 新北市 | AD30: 6.924444 | AE30: 93.075556 | AF30: 100 | AI30: 新北市 | AJ30: 6.924444 | AK30: 93.075556 | AL30: 100 | AO30: 新北市 | AP30: 0 | AS30: 新北市 | AT30: 0 | AW30: 新北市 | AX30: 0
E31: 桃園市 | F31: 8.8669226 | G31: 91.133077 | H31: 100 | K31: 桃園市 | L31: 0.43575267 | M31: -0.43575267 | N31: 0 | Q31: 桃園市 | R31: 8.4311699 | S31: 91.56883 | T31: 100 | W31: 桃園市 | X31: -0.69275443 | Y31: 0.69275443 | Z31: 0 | AC31: 桃園市 | AD31: 9.1239244 | AE31: 90.876076 | AF31: 100 | AI31: 桃園市 | AJ31: 9.1239244 | AK31: 90.876076 | AL31: 100 | AO31: 桃園市 | AP31: 0 | AS31: 桃園市 | AT31: 0 | AW31: 桃園市 | AX31: 0
E32: 臺中市 | F32: 8.7373956 | G32: 91.262604 | H32: 100 | K32: 臺中市 | L32: 0.58507719 | M32: -0.58507719 | N32: 0 | Q32: 臺中市 | R32: 8.1523184 | S32: 91.847682 | T32: 100 | W32: 臺中市 | X32: -0.55294256 | Y32: 0.55294256 | Z32: 0 | AC32: 臺中市 | AD32: 8.705261 | AE32: 91.294739 | AF32: 100 | AI32: 臺中市 | AJ32: 8.705261 | AK32: 91.294739 | AL32: 100 | AO32: 臺中市 | AP32: 0 | AS32: 臺中市 | AT32: 0 | AW32: 臺中市 | AX32: 0
E33: 臺南市 | F33: 9.8557589 | G33: 90.144241 | H33: 100 | K33: 臺南市 | L33: 0.94729231 | M33: -0.94729231 | N33: 0 | Q33: 臺南市 | R33: 8.9084666 | S33: 91.091533 | T33: 100 | W33: 臺南市 | X33: 0.046103908 | Y33: -0.046103908 | Z33: 0 | AC33: 臺南市 | AD33: 8.8623627 | AE33: 91.137637 | AF33: 100 | AI33: 臺南市 | AJ33: 8.8623627 | AK33: 91.137637 | AL33: 100 | AO33: 臺南市 | AP33: 0 | AS33: 臺南市 | AT33: 0 | AW33: 臺南市 | AX33: 0
E34: 高雄市 | F34: 10.325417 | G34: 89.674583 | H34: 100 | K34: 高雄市 | L34: 0.48323273 | M34: -0.48323273 | N34: 0 | Q34: 高雄市 | R34: 9.8421838 | S34: 90.157816 | T34: 100 | W34: 高雄市 | X34: -0.064317307 | Y34: 0.064317307 | Z34: 0 | AC34: 高雄市 | AD34: 9.9065011 | AE34: 90.093499 | AF34: 100 | AI34: 高雄市 | AJ34: 9.9065011 | AK34: 90.093499 | AL34: 100 | AO34: 高雄市 | AP34: 0 | AS34: 高雄市 | AT34: 0 | AW34: 高雄市 | AX34: 0
E35: 基隆市 | F35: 11.022648 | G35: 88.977352 | H35: 100 | K35: 基隆市 | L35: -0.015268002 | M35: 0.015268002 | N35: 0 | Q35: 基隆市 | R35: 11.037916 | S35: 88.962084 | T35: 100 | W35: 基隆市 | X35: 0.11627826 | Y35: -0.11627826 | Z35: 0 | AC35: 基隆市 | AD35: 10.921638 | AE35: 89.078362 | AF35: 100 | AI35: 基隆市 | AJ35: 10.921638 | AK35: 89.078362 | AL35: 100 | AO35: 基隆市 | AP35: 0 | AS35: 基隆市 | AT35: 0 | AW35: 基隆市 | AX35: 0
E36: 新竹市 | F36: 7.7737845 | G36: 92.226216 | H36: 100 | K36: 新竹市 | L36: 0.23762342 | M36: -0.23762342 | N36: 0 | Q36: 新竹市 | R36: 7.5361611 | S36: 92.463839 | T36: 100 | W36: 新竹市 | X36: -0.4803781 | Y36: 0.4803781 | Z36: 0 | AC36: 新竹市 | AD36: 8.0165392 | AE36: 91.983461 | AF36: 100 | AI36: 新竹市 | AJ36: 8.0165392 | AK36: 91.983461 | AL36: 100 | AO36: 新竹市 | AP36: 0 | AS36: 新竹市 | AT36: 0 | AW36: 新竹市 | AX36: 0
E37: 新竹縣 | F37: 8.3208182 | G37: 91.679182 | H37: 100 | K37: 新竹縣 | L37: 0.60581166 | M37: -0.60581166 | N37: 0 | Q37: 新竹縣 | R37: 7.7150065 | S37: 92.284994 | T37: 100 | W37: 新竹縣 | X37: -0.59851614 | Y37: 0.59851614 | Z37: 0 | AC37: 新竹縣 | AD37: 8.3135226 | AE37: 91.686477 | AF37: 100 | AI37: 新竹縣 | AJ37: 8.3135226 | AK37: 91.686477 | AL37: 100 | AO37: 新竹縣 | AP37: 0 | AS37: 新竹縣 | AT37: 0 | AW37: 新竹縣 | AX37: 0
E38: 宜蘭縣 | F38: 14.229903 | G38: 85.770097 | H38: 100 | K38: 宜蘭縣 | L38: 0.10611126 | M38: -0.10611126 | N38: 0 | Q38: 宜蘭縣 | R38: 14.123792 | S38: 85.876208 | T38: 100 | W38: 宜蘭縣 | X38: -0.4025564 | Y38: 0.4025564 | Z38: 0 | AC38: 宜蘭縣 | AD38: 14.526348 | AE38: 85.473652 | AF38: 100 | AI38: 宜蘭縣 | AJ38: 14.526348 | AK38: 85.473652 | AL38: 100 | AO38: 宜蘭縣 | AP38: 0 | AS38: 宜蘭縣 | AT38: 0 | AW38: 宜蘭縣 | AX38: 0
E39: 苗栗縣 | F39: 10.65927 | G39: 89.34073 | H39: 100 | K39: 苗栗縣 | L39: 0.11505213 | M39: -0.11505213 | N39: 0 | Q39: 苗栗縣 | R39: 10.544218 | S39: 89.455782 | T39: 100 | W39: 苗栗縣 | X39: -0.22508328 | Y39: 0.22508328 | Z39: 0 | AC39: 苗栗縣 | AD39: 10.769301 | AE39: 89.230699 | AF39: 100 | AI39: 苗栗縣 | AJ39: 10.769301 | AK39: 89.230699 | AL39: 100 | AO39: 苗栗縣 | AP39: 0 | AS39: 苗栗縣 | AT39: 0 | AW39: 苗栗縣 | AX39: 0
E40: 彰化縣 | F40: 9.8277025 | G40: 90.172297 | H40: 100 | K40: 彰化縣 | L40: 0.35988308 | M40: -0.35988308 | N40: 0 | Q40: 彰化縣 | R40: 9.4678194 | S40: 90.532181 | T40: 100 | W40: 彰化縣 | X40: -0.4324601 | Y40: 0.4324601 | Z40: 0 | AC40: 彰化縣 | AD40: 9.9002795 | AE40: 90.09972 | AF40: 100 | AI40: 彰化縣 | AJ40: 9.9002795 | AK40: 90.09972 | AL40: 100 | AO40: 彰化縣 | AP40: 0 | AS40: 彰化縣 | AT40: 0 | AW40: 彰化縣 | AX40: 0
... E51: 總計 | F51: 8.8219416 | G51: 91.178058 | H51: 100 | K51: 總計 | L51: 0.46572446 | M51: -0.46572446 | N51: 0 | Q51: 總計 | R51: 8.3562172 | S51: 91.643783 | T51: 100 | W51: 總計 | X51: -0.31990757 | Y51: 0.31990757 | Z51: 0 | AC51: 總計 | AD51: 8.6761247 | AE51: 91.323875 | AF51: 100 | AI51: 總計 | AJ51: 8.6761247 | AK51: 91.323875 | AL51: 100 | AO51: 總計 | AP51: 0 | AS51: 總計 | AT51: 0 | AW51: 總計 | AX51: 0
F53: 低度用電 | G53: 非低度用電 | H53: 總計 | L53: 低度用電 | M53: 非低度用電 | N53: 總計 | R53: 低度用電 | S53: 非低度用電 | T53: 總計 | X53: 低度用電 | Y53: 非低度用電 | Z53: 總計 | AD53: 低度用電 | AE53: 非低度用電 | AF53: 總計 | AJ53: 低度用電 | AK53: 非低度用電 | AL53: 總計 | AP53: 總計 | AT53: 總計 | AX53: 總計
E54: 臺北市 | F54: 8.8651227 | G54: 12.007272 | H54: 11.730074 | K54: 臺北市 | L54: -0.8722397 | M54: -0.62072822 | N54: -0.65637882 | Q54: 臺北市 | R54: 9.7373623 | S54: 12.628 | T54: 12.386452 | W54: 臺北市 | X54: 0.22430385 | Y54: 0.097983526 | Z54: 0.1181906 | AC54: 臺北市 | AD54: 9.5130585 | AE54: 12.530017 | AF54: 12.268262 | AI54: 臺北市 | AJ54: 9.5130585 | AK54: 12.530017 | AL54: 12.268262 | AO54: 臺北市 | AP54: 0 | AS54: 臺北市 | AT54: 0 | AW54: 臺北市 | AX54: 0
E55: 新北市 | F55: 17.580323 | G55: 23.047253 | H55: 22.564963 | K55: 新北市 | L55: -0.49152509 | M55: -0.22400531 | N55: -0.27182067 | Q55: 新北市 | R55: 18.071848 | S55: 23.271258 | T55: 22.836784 | W55: 新北市 | X55: -0.1699362 | Y55: -0.023569481 | Z55: -0.019635134 | AC55: 新北市 | AD55: 18.241784 | AE55: 23.294827 | AF55: 22.856419 | AI55: 新北市 | AJ55: 18.241784 | AK55: 23.294827 | AL55: 22.856419 | AO55: 新北市 | AP55: 0 | AS55: 新北市 | AT55: 0 | AW55: 新北市 | AX55: 0
E56: 桃園市 | F56: 10.671143 | G56: 10.611772 | H56: 10.61701 | K56: 桃園市 | L56: -0.037800518 | M56: 0.0067109352 | N56: 0.0032679681 | Q56: 桃園市 | R56: 10.708944 | S56: 10.605061 | T56: 10.613742 | W56: 桃園市 | X56: -0.33161967 | Y56: 0.15784486 | Z56: 0.11504598 | AC56: 桃園市 | AD56: 11.040564 | AE56: 10.447216 | AF56: 10.498696 | AI56: 桃園市 | AJ56: 11.040564 | AK56: 10.447216 | AL56: 10.498696 | AO56: 桃園市 | AP56: 0 | AS56: 桃園市 | AT56: 0 | AW56: 桃園市 | AX56: 0
...

Sheet 表 1‑2
A1: 🏠
A2: ⬅ | B2: 人員 | C2: 到此一遊 | E2: 2024年 | F2: 全國住宅使用現況－按建物總樓層分 | K2: YOY | L2: 全國住宅使用現況－按建物總樓層分 | Q2: 2023年 | R2: 全國住宅使用現況－按建物總樓層分 | W2: YOY | X2: 全國住宅使用現況－按建物總樓層分 | AC2: 2022年 | AD2: 全國住宅使用現況－按建物總樓層分 | AI2: YOY | AJ2: 全國住宅使用現況－按建物總樓層分 | AO2: 2021年 | AP2: 全國住宅使用現況－按建物總樓層分 | AS2: YOY | AT2: 全國住宅使用現況－按建物總樓層分 | AW2: 2020年 | AX2: 全國住宅使用現況－按建物總樓層分
A3: ➡ | B3: 宥婕 | C3: ➖ | F3: 低度用電 | G3: 非低度用電 | H3: 資料缺失 | I3: 總計 | L3: 低度用電 | M3: 非低度用電 | N3: 資料缺失 | O3: 總計 | R3: 低度用電 | S3: 非低度用電 | T3: 資料缺失 | U3: 總計 | X3: 低度用電 | Y3: 非低度用電 | Z3: 資料缺失 | AA3: 總計 | AD3: 低度用電 | AE3: 非低度用電 | AF3: 資料缺失 | AG3: 總計 | AJ3: 低度用電 | AK3: 非低度用電 | AL3: 資料缺失 | AM3: 總計 | AP3: 資料缺失 | AQ3: 總計 | AT3: 資料缺失 | AU3: 總計 | AX3: 資料缺失 | AY3: 總計
B4: 瀚平 | C4: ➖ | E4: 1~5樓 | F4: 347187 | G4: 3503795 | H4: 1578523 | I4: 5429505 | K4: 1~5樓 | L4: 21851 | M4: 85205 | N4: -63297 | O4: 43759 | Q4: 1~5樓 | R4: 325336 | S4: 3418590 | T4: 1641820 | U4: 5385746 | W4: 1~5樓 | X4: -5588 | Y4: 14681 | Z4: 47145 | AA4: 56238 | AC4: 1~5樓 | AD4: 330924 | AE4: 3403909 | AF4: 1594675 | AG4: 5329508 | AI4: 1~5樓 | AJ4: 330924 | AK4: 3403909 | AL4: -3690819 | AM4: 44014 | AO4: 1~5樓 | AP4: 5285494 | AQ4: 5285494 | AS4: 1~5樓 | AT4: 98818 | AU4: 98818 | AW4: 1~5樓 | AX4: 5186676 | AY4: 5186676
B5: 賀翔 | C5: ➖ | E5: 6~10樓 | F5: 79474 | G5: 875092 | H5: 305756 | I5: 1260322 | K5: 6~10樓 | L5: 3864 | M5: -2545 | N5: 14988 | O5: 16307 | Q5: 6~10樓 | R5: 75610 | S5: 877637 | T5: 290768 | U5: 1244015 | W5: 6~10樓 | X5: 833 | Y5: 25269 | Z5: -9755 | AA5: 16347 | AC5: 6~10樓 | AD5: 74777 | AE5: 852368 | AF5: 300523 | AG5: 1227668 | AI5: 6~10樓 | AJ5: 74777 | AK5: 852368 | AL5: -914114 | AM5: 13031 | AO5: 6~10樓 | AP5: 1214637 | AQ5: 1214637 | AS5: 6~10樓 | AT5: 64393 | AU5: 64393 | AW5: 6~10樓 | AX5: 1150244 | AY5: 1150244
B6: 尚書 | C6: ➖ | E6: 11~15樓 | F6: 113447 | G6: 1264534 | H6: 270117 | I6: 1648098 | K6: 11~15樓 | L6: 13113 | M6: 30841 | N6: 11778 | O6: 55732 | Q6: 11~15樓 | R6: 100334 | S6: 1233693 | T6: 258339 | U6: 1592366 | W6: 11~15樓 | X6: -4631 | Y6: 47694 | Z6: 5597 | AA6: 48660 | AC6: 11~15樓 | AD6: 104965 | AE6: 1185999 | AF6: 252742 | AG6: 1543706 | AI6: 11~15樓 | AJ6: 104965 | AK6: 1185999 | AL6: -1241777 | AM6: 49187 | AO6: 11~15樓 | AP6: 1494519 | AQ6: 1494519 | AS6: 11~15樓 | AT6: 75981 | AU6: 75981 | AW6: 11~15樓 | AX6: 1418538 | AY6: 1418538
B7: 文琪 | C7: ➖ | E7: 16~20樓 | F7: 27347 | G7: 298283 | H7: 62241 | I7: 387871 | K7: 16~20樓 | L7: 2384 | M7: 7563 | N7: -96 | O7: 9851 | Q7: 16~20樓 | R7: 24963 | S7: 290720 | T7: 62337 | U7: 378020 | W7: 16~20樓 | X7: -908 | Y7: 7748 | Z7: 2970 | AA7: 9810 | AC7: 16~20樓 | AD7: 25871 | AE7: 282972 | AF7: 59367 | AG7: 368210 | AI7: 16~20樓 | AJ7: 25871 | AK7: 282972 | AL7: -302196 | AM7: 6647 | AO7: 16~20樓 | AP7: 361563 | AQ7: 361563 | AS7: 16~20樓 | AT7: 14213 | AU7: 14213 | AW7: 16~20樓 | AX7: 347350 | AY7: 347350
B8: 育誠 | C8: ➖ | E8: 21樓以上 | F8: 35754 | G8: 296675 | H8: 59018 | I8: 391447 | K8: 21樓以上 | L8: 6113 | M8: 16878 | N8: 327 | O8: 23318 | Q8: 21樓以上 | R8: 29641 | S8: 279797 | T8: 58691 | U8: 368129 | W8: 21樓以上 | X8: -2482 | Y8: 13280 | Z8: 7086 | AA8: 17884 | AC8: 21樓以上 | AD8: 32123 | AE8: 266517 | AF8: 51605 | AG8: 350245 | AI8: 21樓以上 | AJ8: 32123 | AK8: 266517 | AL8: -285792 | AM8: 12848 | AO8: 21樓以上 | AP8: 337397 | AQ8: 337397 | AS8: 21樓以上 | AT8: 21756 | AU8: 21756 | AW8: 21樓以上 | AX8: 315641 | AY8: 315641
B9: 會議 | C9: ➖ | E9: 不明 | F9: 1103 | G9: 7411 | H9: 8185 | I9: 16699 | K9: 不明 | L9: 60 | M9: -47 | N9: -100 | O9: -87 | Q9: 不明 | R9: 1043 | S9: 7458 | T9: 8285 | U9: 16786 | W9: 不明 | X9: -1228 | Y9: -10330 | Z9: -5923 | AA9: -17481 | AC9: 不明 | AD9: 2271 | AE9: 17788 | AF9: 14208 | AG9: 34267 | AI9: 不明 | AJ9: 2271 | AK9: 17788 | AL9: -17968 | AM9: 2091 | AO9: 不明 | AP9: 32176 | AQ9: 32176 | AS9: 不明 | AT9: 3028 | AU9: 3028 | AW9: 不明 | AX9: 29148 | AY9: 29148
E10: 總計 | F10: 604312 | G10: 6245790 | H10: 2283840 | I10: 9133942 | K10: 總計 | L10: 47385 | M10: 137895 | N10: -36400 | O10: 148880 | Q10: 總計 | R10: 556927 | S10: 6107895 | T10: 2320240 | U10: 8985062 | W10: 總計 | X10: -14004 | Y10: 98342 | Z10: 47120 | AA10: 131458 | AC10: 總計 | AD10: 570931 | AE10: 6009553 | AF10: 2273120 | AG10: 8853604 | AI10: 總計 | AJ10: 570931 | AK10: 6009553 | AL10: -6452666 | AM10: 127818 | AO10: 總計 | AP10: 8725786 | AQ10: 8725786 | AS10: 總計 | AT10: 278189 | AU10: 278189 | AW10: 總計 | AX10: 8447597 | AY10: 8447597
F12: 低度用電 | G12: 非低度用電 | H12: 總計 | L12: 低度用電 | M12: 非低度用電 | N12: 總計 | R12: 低度用電 | S12: 非低度用電 | T12: 總計 | X12: 低度用電 | Y12: 非低度用電 | Z12: 總計 | AD12: 低度用電 | AE12: 非低度用電 | AF12: 總計 | AJ12: 低度用電 | AK12: 非低度用電 | AL12: 總計 | AP12: 總計 | AT12: 總計 | AX12: 總計
E13: 1~5樓 | F13: 9.0155446 | G13: 90.984455 | H13: 100 | K13: 1~5樓 | L13: 0.32584294 | M13: -0.32584294 | N13: 0 | Q13: 1~5樓 | R13: 8.6897017 | S13: 91.310298 | T13: 100 | W13: 1~5樓 | X13: -0.17077483 | Y13: 0.17077483 | Z13: 0 | AC13: 1~5樓 | AD13: 8.8604765 | AE13: 91.139524 | AF13: 100 | AI13: 1~5樓 | AJ13: 8.8604765 | AK13: 91.139524 | AL13: 100 | AO13: 1~5樓 | AP13: 0 | AS13: 1~5樓 | AT13: 0 | AW13: 1~5樓 | AX13: 0
E14: 6~10樓 | F14: 8.3256684 | G14: 91.674332 | H14: 100 | K14: 6~10樓 | L14: 0.39383124 | M14: -0.39383124 | N14: 0 | Q14: 6~10樓 | R14: 7.9318372 | S14: 92.068163 | T14: 100 | W14: 6~10樓 | X14: -0.13346005 | Y14: 0.13346005 | Z14: 0 | AC14: 6~10樓 | AD14: 8.0652972 | AE14: 91.934703 | AF14: 100 | AI14: 6~10樓 | AJ14: 8.0652972 | AK14: 91.934703 | AL14: 100 | AO14: 6~10樓 | AP14: 0 | AS14: 6~10樓 | AT14: 0 | AW14: 6~10樓 | AX14: 0
E15: 11~15樓 | F15: 8.2328421 | G15: 91.767158 | H15: 100 | K15: 11~15樓 | L15: 0.71170498 | M15: -0.71170498 | N15: 0 | Q15: 11~15樓 | R15: 7.5211371 | S15: 92.478863 | T15: 100 | W15: 11~15樓 | X15: -0.60960858 | Y15: 0.60960858 | Z15: 0 | AC15: 11~15樓 | AD15: 8.1307457 | AE15: 91.869254 | AF15: 100 | AI15: 11~15樓 | AJ15: 8.1307457 | AK15: 91.869254 | AL15: 100 | AO15: 11~15樓 | AP15: 0 | AS15: 11~15樓 | AT15: 0 | AW15: 11~15樓 | AX15: 0
E16: 16~20樓 | F16: 8.398182 | G16: 91.601818 | H16: 100 | K16: 16~20樓 | L16: 0.4905658 | M16: -0.4905658 | N16: 0 | Q16: 16~20樓 | R16: 7.9076162 | S16: 92.092384 | T16: 100 | W16: 16~20樓 | X16: -0.46913187 | Y16: 0.46913187 | Z16: 0 | AC16: 16~20樓 | AD16: 8.3767481 | AE16: 91.623252 | AF16: 100 | AI16: 16~20樓 | AJ16: 8.3767481 | AK16: 91.623252 | AL16: 100 | AO16: 16~20樓 | AP16: 0 | AS16: 16~20樓 | AT16: 0 | AW16: 16~20樓 | AX16: 0
E17: 21樓以上 | F17: 10.755379 | G17: 89.244621 | H17: 100 | K17: 21樓以上 | L17: 1.1764007 | M17: -1.1764007 | N17: 0 | Q17: 21樓以上 | R17: 9.5789787 | S17: 90.421021 | T17: 100 | W17: 21樓以上 | X17: -1.1774505 | Y17: 1.1774505 | Z17: 0 | AC17: 21樓以上 | AD17: 10.756429 | AE17: 89.243571 | AF17: 100 | AI17: 21樓以上 | AJ17: 10.756429 | AK17: 89.243571 | AL17: 100 | AO17: 21樓以上 | AP17: 0 | AS17: 21樓以上 | AT17: 0 | AW17: 21樓以上 | AX17: 0
E18: 總計 | F18: 8.8167981 | G18: 91.183202 | H18: 100 | K18: 總計 | L18: 0.46557825 | M18: -0.46557825 | N18: 0 | Q18: 總計 | R18: 8.3512198 | S18: 91.64878 | T18: 100 | W18: 總計 | X18: -0.31681615 | Y18: 0.31681615 | Z18: 0 | AC18: 總計 | AD18: 8.668036 | AE18: 91.331964 | AF18: 100 | AI18: 總計 | AJ18: 8.668036 | AK18: 91.331964 | AL18: 100 | AO18: 總計 | AP18: 0 | AS18: 總計 | AT18: 0 | AW18: 總計 | AX18: 0
F20: 低度用電 | G20: 非低度用電 | H20: 總計 | L20: 低度用電 | M20: 非低度用電 | N20: 總計 | R20: 低度用電 | S20: 非低度用電 | T20: 總計 | X20: 低度用電 | Y20: 非低度用電 | Z20: 總計 | AD20: 低度用電 | AE20: 非低度用電 | AF20: 總計 | AJ20: 低度用電 | AK20: 非低度用電 | AL20: 總計 | AP20: 總計 | AT20: 總計 | AX20: 總計
E21: 1~5樓 | F21: 57.556668 | G21: 56.165151 | H21: 56.287838 | K21: 1~5樓 | L21: -0.96921174 | M21: 0.12670678 | N21: 0.04166281 | Q21: 1~5樓 | R21: 58.52588 | S21: 56.038444 | T21: 56.246176 | W21: 1~5樓 | X21: 0.33223127 | Y21: -0.77134364 | Z21: -0.68356597 | AC21: 1~5樓 | AD21: 58.193648 | AE21: 56.809788 | AF21: 56.929742 | AI21: 1~5樓 | AJ21: 58.193648 | AK21: 56.809788 | AL21: 56.929742 | AO21: 1~5樓 | AP21: 0 | AS21: 1~5樓 | AT21: 0 | AW21: 1~5樓 | AX21: 0
E22: 6~10樓 | F22: 13.175201 | G22: 14.027554 | H22: 13.952404 | K22: 6~10樓 | L22: -0.42655734 | M22: -0.35890689 | N22: -0.3685249 | Q22: 6~10樓 | R22: 13.601759 | S22: 14.386461 | T22: 14.320929 | W22: 6~10樓 | X22: 0.45207342 | Y22: 0.16080312 | Z22: 0.1885366 | AC22: 6~10樓 | AD22: 13.149685 | AE22: 14.225658 | AF22: 14.132392 | AI22: 6~10樓 | AJ22: 13.149685 | AK22: 14.225658 | AL22: 14.132392 | AO22: 6~10樓 | AP22: 0 | AS22: 6~10樓 | AT22: 0 | AW22: 6~10樓 | AX22: 0
E23: 11~15樓 | F23: 18.807246 | G23: 20.270234 | H23: 20.141245 | K23: 11~15樓 | L23: 0.75779675 | M23: 0.047207016 | N23: 0.099738574 | Q23: 11~15樓 | R23: 18.049449 | S23: 20.223027 | T23: 20.041506 | W23: 11~15樓 | X23: -0.40885632 | Y23: 0.42920963 | Z23: 0.36345202 | AC23: 11~15樓 | AD23: 18.458305 | AE23: 19.793817 | AF23: 19.678054 | AI23: 11~15樓 | AJ23: 18.458305 | AK23: 19.793817 | AL23: 19.678054 | AO23: 11~15樓 | AP23: 0 | AS23: 11~15樓 | AT23: 0 | AW23: 11~15樓 | AX23: 0
E24: 16~20樓 | F24: 4.5335862 | G24: 4.7814184 | H24: 4.7595675 | K24: 16~20樓 | L24: 0.042901096 | M24: 0.01585814 | N24: 0.016962704 | Q24: 16~20樓 | R24: 4.4906851 | S24: 4.7655602 | T24: 4.7426048 | W24: 16~20樓 | X24: -0.058782061 | Y24: 0.042878357 | Z24: 0.034937244 | AC24: 16~20樓 | AD24: 4.5494672 | AE24: 4.7226819 | AF24: 4.7076676 | AI24: 16~20樓 | AJ24: 4.5494672 | AK24: 4.7226819 | AL24: 4.7076676 | AO24: 16~20樓 | AP24: 0 | AS24: 16~20樓 | AT24: 0 | AW24: 16~20樓 | AX24: 0
E25: 21樓以上 | F25: 5.9272988 | G25: 4.7556425 | H25: 4.858945 | K25: 21樓以上 | L25: 0.59507124 | M25: 0.16913496 | N25: 0.21016081 | Q25: 21樓以上 | R25: 5.3322276 | S25: 4.5865075 | T25: 4.6487842 | W25: 21樓以上 | X25: -0.3166663 | Y25: 0.13845254 | Z25: 0.096640109 | AC25: 21樓以上 | AD25: 5.6488939 | AE25: 4.448055 | AF25: 4.5521441 | AI25: 21樓以上 | AJ25: 5.6488939 | AK25: 4.448055 | AL25: 4.5521441 | AO25: 21樓以上 | AP25: 0 | AS25: 21樓以上 | AT25: 0 | AW25: 21樓以上 | AX25: 0
E26: 總計 | F26: 100 | G26: 100 | H26: 100 | K26: 總計 | L26: 0 | M26: 0 | N26: 0 | Q26: 總計 | R26: 100 | S26: 100 | T26: 100 | W26: 總計 | X26: 0 | Y26: 0 | Z26: 0 | AC26: 總計 | AD26: 100 | AE26: 100 | AF26: 100 | AI26: 總計 | AJ26: 100 | AK26: 100 | AL26: 100 | AO26: 總計 | AP26: 0 | AS26: 總計 | AT26: 0 | AW26: 總計 | AX26: 0
F28: 低度用電 | G28: 非低度用電 | H28: 總計 | L28: 低度用電 | M28: 非低度用電 | N28: 總計 | R28: 低度用電 | S28: 非低度用電 | T28: 總計 | X28: 低度用電 | Y28: 非低度用電 | Z28: 總計 | AD28: 低度用電 | AE28: 非低度用電 | AF28: 總計 | AJ28: 低度用電 | AK28: 非低度用電 | AL28: 總計 | AP28: 總計 | AT28: 總計 | AX28: 總計
E29: 1~5樓 | F29: 5.0746552 | G29: 51.213183 | H29: 56.287838 | K29: 1~5樓 | L29: 0.18703032 | M29: -0.14536751 | N29: 0.04166281 | Q29: 1~5樓 | R29: 4.8876249 | S29: 51.358551 | T29: 56.246176 | W29: 1~5樓 | X29: -0.15662151 | Y29: -0.52694446 | Z29: -0.68356597 | AC29: 1~5樓 | AD29: 5.0442464 | AE29: 51.885495 | AF29: 56.929742 | AI29: 1~5樓 | AJ29: 5.0442464 | AK29: 51.885495 | AL29: 56.929742 | AO29: 1~5樓 | AP29: 0 | AS29: 1~5樓 | AT29: 0 | AW29: 1~5樓 | AX29: 0
E30: 6~10樓 | F30: 1.1616309 | G30: 12.790773 | H30: 13.952404 | K30: 6~10樓 | L30: 0.02571813 | M30: -0.39424303 | N30: -0.3685249 | Q30: 6~10樓 | R30: 1.1359128 | S30: 13.185016 | T30: 14.320929 | W30: 6~10樓 | X30: -0.0039066814 | Y30: 0.19244328 | Z30: 0.1885366 | AC30: 6~10樓 | AD30: 1.1398194 | AE30: 12.992573 | AF30: 14.132392 | AI30: 6~10樓 | AJ30: 1.1398194 | AK30: 12.992573 | AL30: 14.132392 | AO30: 6~10樓 | AP30: 0 | AS30: 6~10樓 | AT30: 0 | AW30: 6~10樓 | AX30: 0
E31: 11~15樓 | F31: 1.6581969 | G31: 18.483048 | H31: 20.141245 | K31: 11~15樓 | L31: 0.15084772 | M31: -0.051109144 | N31: 0.099738574 | Q31: 11~15樓 | R31: 1.5073492 | S31: 18.534157 | T31: 20.041506 | W31: 11~15樓 | X31: -0.092623383 | Y31: 0.4560754 | Z31: 0.36345202 | AC31: 11~15樓 | AD31: 1.5999726 | AE31: 18.078082 | AF31: 19.678054 | AI31: 11~15樓 | AJ31: 1.5999726 | AK31: 18.078082 | AL31: 19.678054 | AO31: 11~15樓 | AP31: 0 | AS31: 11~15樓 | AT31: 0 | AW31: 11~15樓 | AX31: 0
E32: 16~20樓 | F32: 0.39971714 | G32: 4.3598504 | H32: 4.7595675 | K32: 16~20樓 | L32: 0.024690156 | M32: -0.0077274517 | N32: 0.016962704 | Q32: 16~20樓 | R32: 0.37502699 | S32: 4.3675778 | T32: 4.7426048 | W32: 16~20樓 | X32: -0.019322466 | Y32: 0.05425971 | Z32: 0.034937244 | AC32: 16~20樓 | AD32: 0.39434945 | AE32: 4.3133181 | AF32: 4.7076676 | AI32: 16~20樓 | AJ32: 0.39434945 | AK32: 4.3133181 | AL32: 4.7076676 | AO32: 16~20樓 | AP32: 0 | AS32: 16~20樓 | AT32: 0 | AW32: 16~20樓 | AX32: 0
E33: 21樓以上 | F33: 0.52259797 | G33: 4.3363471 | H33: 4.858945 | K33: 21樓以上 | L33: 0.077291922 | M33: 0.13286889 | N33: 0.21016081 | Q33: 21樓以上 | R33: 0.44530605 | S33: 4.2034782 | T33: 4.6487842 | W33: 21樓以上 | X33: -0.044342107 | Y33: 0.14098222 | Z33: 0.096640109 | AC33: 21樓以上 | AD33: 0.48964816 | AE33: 4.062496 | AF33: 4.5521441 | AI33: 21樓以上 | AJ33: 0.48964816 | AK33: 4.062496 | AL33: 4.5521441 | AO33: 21樓以上 | AP33: 0 | AS33: 21樓以上 | AT33: 0 | AW33: 21樓以上 | AX33: 0
E34: 總計 | F34: 8.8167981 | G34: 91.183202 | H34: 100 | K34: 總計 | L34: 0.46557825 | M34: -0.46557825 | N34: 0 | Q34: 總計 | R34: 8.3512198 | S34: 91.64878 | T34: 100 | W34: 總計 | X34: -0.31681615 | Y34: 0.31681615 | Z34: 0 | AC34: 總計 | AD34: 8.668036 | AE34: 91.331964 | AF34: 100 | AI34: 總計 | AJ34: 8.668036 | AK34: 91.331964 | AL34: 100 | AO34: 總計 | AP34: 0 | AS34: 總計 | AT34: 0 | AW34: 總計 | AX34: 0

Sheet 表 1‑3
A1: 🏠
A2: ⬅ | B2: 人員 | C2: 到此一遊 | E2: 2024年 | F2: 全國住宅使用現況－按建物屋齡分 | K2: YOY | L2: 全國住宅使用現況－按建物屋齡分 | Q2: 2023年 | R2: 全國住宅使用現況－按建物屋齡分 | W2: YOY | X2: 全國住宅使用現況－按建物屋齡分 | AC2: 2022年 | AD2: 全國住宅使用現況－按建物屋齡分 | AI2: YOY | AJ2: 全國住宅使用現況－按建物屋齡分 | AO2: 2021年 | AP2: 全國住宅使用現況－按建物屋齡分 | AS2: YOY | AT2: 全國住宅使用現況－按建物屋齡分 | AW2: 2020年 | AX2: 全國住宅使用現況－按建物屋齡分
A3: ➡ | B3: 宥婕 | C3: ➖ | F3: 低度用電 | G3: 非低度用電 | H3: 資料缺失 | I3: 總計 | L3: 低度用電 | M3: 非低度用電 | N3: 資料缺失 | O3: 總計 | R3: 低度用電 | S3: 非低度用電 | T3: 資料缺失 | U3: 總計 | X3: 低度用電 | Y3: 非低度用電 | Z3: 資料缺失 | AA3: 總計 | AD3: 低度用電 | AE3: 非低度用電 | AF3: 資料缺失 | AG3: 總計 | AJ3: 低度用電 | AK3: 非低度用電 | AL3: 資料缺失 | AM3: 總計 | AP3: 資料缺失 | AQ3: 總計 | AT3: 資料缺失 | AU3: 總計 | AX3: 資料缺失 | AY3: 總計
B4: 瀚平 | C4: ➖ | E4: 0~4年 | F4: 79748 | G4: 346374 | H4: 132087 | I4: 558209 | K4: 0~4年 | L4: 20490 | M4: 18046 | N4: 2668 | O4: 41204 | Q4: 0~4年 | R4: 59258 | S4: 328328 | T4: 129419 | U4: 517005 | W4: 0~4年 | X4: -11812 | Y4: 8354 | Z4: 31571 | AA4: 28113 | AC4: 0~4年 | AD4: 71070 | AE4: 319974 | AF4: 97848 | AG4: 488892 | AI4: 0~4年 | AJ4: 71070 | AK4: 319974 | AL4: -368779 | AM4: 22265 | AO4: 0~4年 | AP4: 466627 | AQ4: 466627 | AS4: 0~4年 | AT4: 7736 | AU4: 7736 | AW4: 0~4年 | AX4: 458891 | AY4: 458891
B5: 賀翔 | C5: ➖ | E5: 5~9年 | F5: 32846 | G5: 400687 | H5: 113122 | I5: 546655 | K5: 5~9年 | L5: -1338 | M5: 869 | N5: -1016 | O5: -1485 | Q5: 5~9年 | R5: 34184 | S5: 399818 | T5: 114138 | U5: 548140 | W5: 5~9年 | X5: -997 | Y5: 15545 | Z5: -4366 | AA5: 10182 | AC5: 5~9年 | AD5: 35181 | AE5: 384273 | AF5: 118504 | AG5: 537958 | AI5: 5~9年 | AJ5: 35181 | AK5: 384273 | AL5: -414287 | AM5: 5167 | AO5: 5~9年 | AP5: 532791 | AQ5: 532791 | AS5: 5~9年 | AT5: 32154 | AU5: 32154 | AW5: 5~9年 | AX5: 500637 | AY5: 500637
B6: 尚書 | C6: ➖ | E6: 10~19年 | F6: 52054 | G6: 799000 | H6: 322678 | I6: 1173732 | K6: 10~19年 | L6: -243 | M6: -5845 | N6: -8977 | O6: -15065 | Q6: 10~19年 | R6: 52297 | S6: 804845 | T6: 331655 | U6: 1188797 | W6: 10~19年 | X6: 1011 | Y6: 24016 | Z6: -19655 | AA6: 5372 | AC6: 10~19年 | AD6: 51286 | AE6: 780829 | AF6: 351310 | AG6: 1183425 | AI6: 10~19年 | AJ6: 51286 | AK6: 780829 | AL6: -814678 | AM6: 17437 | AO6: 10~19年 | AP6: 1165988 | AQ6: 1165988 | AS6: 10~19年 | AT6: 29455 | AU6: 29455 | AW6: 10~19年 | AX6: 1136533 | AY6: 1136533
B7: 文琪 | C7: ➖ | E7: 20~29年 | F7: 103223 | G7: 1258866 | H7: 485115 | I7: 1847204 | K7: 20~29年 | L7: -16699 | M7: -214800 | N7: -59457 | O7: -290956 | Q7: 20~29年 | R7: 119922 | S7: 1473666 | T7: 544572 | U7: 2138160 | W7: 20~29年 | X7: -16465 | Y7: -138262 | Z7: -66044 | AA7: -220771 | AC7: 20~29年 | AD7: 136387 | AE7: 1611928 | AF7: 610616 | AG7: 2358931 | AI7: 20~29年 | AJ7: 136387 | AK7: 1611928 | AL7: -1872184 | AM7: -123869 | AO7: 20~29年 | AP7: 2482800 | AQ7: 2482800 | AS7: 20~29年 | AT7: 13239 | AU7: 13239 | AW7: 20~29年 | AX7: 2469561 | AY7: 2469561
B8: 育誠 | C8: ➖ | E8: 30~39年 | F8: 112022 | G8: 1346948 | H8: 513266 | I8: 1972236 | K8: 30~39年 | L8: 21938 | M8: 189737 | N8: 28993 | O8: 240668 | Q8: 30~39年 | R8: 90084 | S8: 1157211 | T8: 484273 | U8: 1731568 | W8: 30~39年 | X8: 5193 | Y8: 82299 | Z8: 43777 | AA8: 131269 | AC8: 30~39年 | AD8: 84891 | AE8: 1074912 | AF8: 440496 | AG8: 1600299 | AI8: 30~39年 | AJ8: 84891 | AK8: 1074912 | AL8: -1135406 | AM8: 24397 | AO8: 30~39年 | AP8: 1575902 | AQ8: 1575902 | AS8: 30~39年 | AT8: -153963 | AU8: -153963 | AW8: 30~39年 | AX8: 1729865 | AY8: 1729865
B9: 會議 | C9: ➖ | E9: 40~49年 | F9: 150563 | G9: 1484260 | H9: 447881 | I9: 2082704 | K9: 40~49年 | L9: 11399 | M9: 70283 | N9: -891 | O9: 80791 | Q9: 40~49年 | R9: 139164 | S9: 1413977 | T9: 448772 | U9: 2001913 | W9: 40~49年 | X9: 3921 | Y9: 59948 | Z9: 35425 | AA9: 99294 | AC9: 40~49年 | AD9: 135243 | AE9: 1354029 | AF9: 413347 | AG9: 1902619 | AI9: 40~49年 | AJ9: 135243 | AK9: 1354029 | AL9: -1337732 | AM9: 151540 | AO9: 40~49年 | AP9: 1751079 | AQ9: 1751079 | AS9: 40~49年 | AT9: 321201 | AU9: 321201 | AW9: 40~49年 | AX9: 1429878 | AY9: 1429878
E10: 50年以上 | F10: 52580 | G10: 413070 | H10: 165856 | I10: 631506 | K10: 50年以上 | L10: 10966 | M10: 84331 | N10: 14210 | O10: 109507 | Q10: 50年以上 | R10: 41614 | S10: 328739 | T10: 151646 | U10: 521999 | W10: 50年以上 | X10: 7142 | Y10: 68735 | Z10: 29902 | AA10: 105779 | AC10: 50年以上 | AD10: 34472 | AE10: 260004 | AF10: 121744 | AG10: 416220 | AI10: 50年以上 | AJ10: 34472 | AK10: 260004 | AL10: -215574 | AM10: 78902 | AO10: 50年以上 | AP10: 337318 | AQ10: 337318 | AS10: 50年以上 | AT10: 65092 | AU10: 65092 | AW10: 50年以上 | AX10: 272226 | AY10: 272226
E11: 資料缺失 | F11: 21276 | G11: 196585 | H11: 103835 | I11: 321696 | K11: 資料缺失 | L11: 872 | M11: -4726 | N11: -11930 | O11: -15784 | Q11: 資料缺失 | R11: 20404 | S11: 201311 | T11: 115765 | U11: 337480 | W11: 資料缺失 | X11: -1997 | Y11: -22293 | Z11: -3490 | AA11: -27780 | AC11: 資料缺失 | AD11: 22401 | AE11: 223604 | AF11: 119255 | AG11: 365260 | AI11: 資料缺失 | AJ11: 22401 | AK11: 223604 | AL11: -294026 | AM11: -48021 | AO11: 資料缺失 | AP11: 413281 | AQ11: 413281 | AS11: 資料缺失 | AT11: -36725 | AU11: -36725 | AW11: 資料缺失 | AX11: 450006 | AY11: 450006
E12: 總計 | F12: 604312 | G12: 6245790 | H12: 2283840 | I12: 9133942 | K12: 總計 | L12: 47385 | M12: 137895 | N12: -36400 | O12: 148880 | Q12: 總計 | R12: 556927 | S12: 6107895 | T12: 2320240 | U12: 8985062 | W12: 總計 | X12: -14004 | Y12: 98342 | Z12: 47120 | AA12: 131458 | AC12: 總計 | AD12: 570931 | AE12: 6009553 | AF12: 2273120 | AG12: 8853604 | AI12: 總計 | AJ12: 570931 | AK12: 6009553 | AL12: -6452666 | AM12: 127818 | AO12: 總計 | AP12: 8725786 | AQ12: 8725786 | AS12: 總計 | AT12: 278189 | AU12: 278189 | AW12: 總計 | AX12: 8447597 | AY12: 8447597
F14: 低度用電 | G14: 非低度用電 | H14: 總計 | L14: 低度用電 | M14: 非低度用電 | N14: 總計 | R14: 低度用電 | S14: 非低度用電 | T14: 總計 | X14: 低度用電 | Y14: 非低度用電 | Z14: 總計 | AD14: 低度用電 | AE14: 非低度用電 | AF14: 總計 | AJ14: 低度用電 | AK14: 非低度用電 | AL14: 總計 | AP14: 總計 | AT14: 總計 | AX14: 總計
E15: 0~4年 | F15: 18.714828 | G15: 81.285172 | H15: 100 | K15: 0~4年 | L15: 3.4258342 | M15: -3.4258342 | N15: 0 | Q15: 0~4年 | R15: 15.288994 | S15: 84.711006 | T15: 100 | W15: 0~4年 | X15: -2.8854315 | Y15: 2.8854315 | Z15: 0 | AC15: 0~4年 | AD15: 18.174425 | AE15: 81.825575 | AF15: 100 | AI15: 0~4年 | AJ15: 18.174425 | AK15: 81.825575 | AL15: 100 | AO15: 0~4年 | AP15: 0 | AS15: 0~4年 | AT15: 0 | AW15: 0~4年 | AX15: 0
E16: 5~9年 | F16: 7.5763552 | G16: 92.423645 | H16: 100 | K16: 5~9年 | L16: -0.3001062 | M16: 0.3001062 | N16: 0 | Q16: 5~9年 | R16: 7.8764614 | S16: 92.123539 | T16: 100 | W16: 5~9年 | X16: -0.5108707 | Y16: 0.5108707 | Z16: 0 | AC16: 5~9年 | AD16: 8.3873321 | AE16: 91.612668 | AF16: 100 | AI16: 5~9年 | AJ16: 8.3873321 | AK16: 91.612668 | AL16: 100 | AO16: 5~9年 | AP16: 0 | AS16: 5~9年 | AT16: 0 | AW16: 5~9年 | AX16: 0
E17: 10~19年 | F17: 6.1164156 | G17: 93.883584 | H17: 100 | K17: 10~19年 | L17: 0.015092877 | M17: -0.015092877 | N17: 0 | Q17: 10~19年 | R17: 6.1013228 | S17: 93.898677 | T17: 100 | W17: 10~19年 | X17: -0.062008022 | Y17: 0.062008022 | Z17: 0 | AC17: 10~19年 | AD17: 6.1633308 | AE17: 93.836669 | AF17: 100 | AI17: 10~19年 | AJ17: 6.1633308 | AK17: 93.836669 | AL17: 100 | AO17: 10~19年 | AP17: 0 | AS17: 10~19年 | AT17: 0 | AW17: 10~19年 | AX17: 0
E18: 20~29年 | F18: 7.578286 | G18: 92.421714 | H18: 100 | K18: 20~29年 | L18: 0.053003431 | M18: -0.053003431 | N18: 0 | Q18: 20~29年 | R18: 7.5252826 | S18: 92.474717 | T18: 100 | W18: 20~29年 | X18: -0.27577159 | Y18: 0.27577159 | Z18: 0 | AC18: 20~29年 | AD18: 7.8010542 | AE18: 92.198946 | AF18: 100 | AI18: 20~29年 | AJ18: 7.8010542 | AK18: 92.198946 | AL18: 100 | AO18: 20~29年 | AP18: 0 | AS18: 20~29年 | AT18: 0 | AW18: 20~29年 | AX18: 0
E19: 30~39年 | F19: 7.6781565 | G19: 92.321843 | H19: 100 | K19: 30~39年 | L19: 0.45580734 | M19: -0.45580734 | N19: 0 | Q19: 30~39年 | R19: 7.2223492 | S19: 92.777651 | T19: 100 | W19: 30~39年 | X19: -0.097083533 | Y19: 0.097083533 | Z19: 0 | AC19: 30~39年 | AD19: 7.3194327 | AE19: 92.680567 | AF19: 100 | AI19: 30~39年 | AJ19: 7.3194327 | AK19: 92.680567 | AL19: 100 | AO19: 30~39年 | AP19: 0 | AS19: 30~39年 | AT19: 0 | AW19: 30~39年 | AX19: 0
E20: 40~49年 | F20: 9.2097432 | G20: 90.790257 | H20: 100 | K20: 40~49年 | L20: 0.24957796 | M20: -0.24957796 | N20: 0 | Q20: 40~49年 | R20: 8.9601652 | S20: 91.039835 | T20: 100 | W20: 40~49年 | X20: -0.12098313 | Y20: 0.12098313 | Z20: 0 | AC20: 40~49年 | AD20: 9.0811484 | AE20: 90.918852 | AF20: 100 | AI20: 40~49年 | AJ20: 9.0811484 | AK20: 90.918852 | AL20: 100 | AO20: 40~49年 | AP20: 0 | AS20: 40~49年 | AT20: 0 | AW20: 40~49年 | AX20: 0
E21: 50年以上 | F21: 11.291743 | G21: 88.708257 | H21: 100 | K21: 50年以上 | L21: 0.055435742 | M21: -0.055435742 | N21: 0 | Q21: 50年以上 | R21: 11.236307 | S21: 88.763693 | T21: 100 | W21: 50年以上 | X21: -0.46991016 | Y21: 0.46991016 | Z21: 0 | AC21: 50年以上 | AD21: 11.706217 | AE21: 88.293783 | AF21: 100 | AI21: 50年以上 | AJ21: 11.706217 | AK21: 88.293783 | AL21: 100 | AO21: 50年以上 | AP21: 0 | AS21: 50年以上 | AT21: 0 | AW21: 50年以上 | AX21: 0
E22: 總計 | F22: 8.7909351 | G22: 91.209065 | H22: 100 | K22: 總計 | L22: 0.46385002 | M22: -0.46385002 | N22: 0 | Q22: 總計 | R22: 8.3270851 | S22: 91.672915 | T22: 100 | W22: 總計 | X22: -0.3323485 | Y22: 0.3323485 | Z22: 0 | AC22: 總計 | AD22: 8.6594336 | AE22: 91.340566 | AF22: 100 | AI22: 總計 | AJ22: 8.6594336 | AK22: 91.340566 | AL22: 100 | AO22: 總計 | AP22: 0 | AS22: 總計 | AT22: 0 | AW22: 總計 | AX22: 0
F24: 低度用電 | G24: 非低度用電 | H24: 總計 | L24: 低度用電 | M24: 非低度用電 | N24: 總計 | R24: 低度用電 | S24: 非低度用電 | T24: 總計 | X24: 低度用電 | Y24: 非低度用電 | Z24: 總計 | AD24: 低度用電 | AE24: 非低度用電 | AF24: 總計 | AJ24: 低度用電 | AK24: 非低度用電 | AL24: 總計 | AP24: 總計 | AT24: 總計 | AX24: 總計
E25: 0~4年 | F25: 13.678058 | G25: 5.7259425 | H25: 6.4250078 | K25: 0~4年 | L25: 2.6332375 | M25: 0.16726425 | N25: 0.40949383 | Q25: 0~4年 | R25: 11.04482 | S25: 5.5586782 | T25: 6.0155139 | W25: 0~4年 | X25: -1.9116272 | Y25: 0.028487781 | Z25: -0.15774829 | AC25: 0~4年 | AD25: 12.956447 | AE25: 5.5301905 | AF25: 6.1732622 | AI25: 0~4年 | AJ25: 12.956447 | AK25: 5.5301905 | AL25: 6.1732622 | AO25: 0~4年 | AP25: 0 | AS25: 0~4年 | AT25: 0 | AW25: 0~4年 | AX25: 0
E26: 5~9年 | F26: 5.6336144 | G26: 6.623796 | H26: 6.5367498 | K26: 5~9年 | L26: -0.73778068 | M26: -0.14522648 | N26: -0.19916193 | Q26: 5~9年 | R26: 6.3713951 | S26: 6.7690225 | T26: 6.7359117 | W26: 5~9年 | X26: -0.042292417 | Y26: 0.12753638 | Z26: 0.11415167 | AC26: 5~9年 | AD26: 6.4136875 | AE26: 6.6414861 | AF26: 6.6217601 | AI26: 5~9年 | AJ26: 6.4136875 | AK26: 6.6414861 | AL26: 6.6217601 | AO26: 5~9年 | AP26: 0 | AS26: 5~9年 | AT26: 0 | AW26: 5~9年 | AX26: 0
E27: 10~19年 | F27: 8.9280936 | G27: 13.208347 | H27: 12.832073 | K27: 10~19年 | L27: -0.81929837 | M27: -0.41788751 | N27: -0.47116729 | Q27: 10~19年 | R27: 9.747392 | S27: 13.626235 | T27: 13.30324 | W27: 10~19年 | X27: 0.39767549 | Y27: 0.13097232 | Z27: 0.16695858 | AC27: 10~19年 | AD27: 9.3497165 | AE27: 13.495262 | AF27: 13.136282 | AI27: 10~19年 | AJ27: 9.3497165 | AK27: 13.495262 | AL27: 13.136282 | AO27: 10~19年 | AP27: 0 | AS27: 10~19年 | AT27: 0 | AW27: 10~19年 | AX27: 0
E28: 20~29年 | F28: 17.704396 | G28: 20.810437 | H28: 20.537387 | K28: 20~29年 | L28: -4.6473023 | M28: -4.1391108 | N28: -4.1958357 | Q28: 20~29年 | R28: 22.351698 | S28: 24.949548 | T28: 24.733223 | W28: 20~29年 | X28: -2.5123934 | Y28: -2.9098059 | Z28: -2.8667583 | AC28: 20~29年 | AD28: 24.864091 | AE28: 27.859354 | AF28: 27.599981 | AI28: 20~29年 | AJ28: 24.864091 | AK28: 27.859354 | AL28: 27.599981 | AO28: 20~29年 | AP28: 0 | AS28: 20~29年 | AT28: 0 | AW28: 20~29年 | AX28: 0
E29: 30~39年 | F29: 19.213565 | G29: 22.266529 | H29: 21.998145 | K29: 30~39年 | L29: 2.4232315 | M29: 2.6746467 | N29: 2.63955 | Q29: 30~39年 | R29: 16.790333 | S29: 19.591883 | T29: 19.358595 | W29: 30~39年 | X29: 1.3142427 | Y29: 1.0139103 | Z29: 1.0492283 | AC29: 30~39年 | AD29: 15.476091 | AE29: 18.577972 | AF29: 18.309367 | AI29: 30~39年 | AJ29: 15.476091 | AK29: 18.577972 | AL29: 18.309367 | AO29: 30~39年 | AP29: 0 | AS29: 30~39年 | AT29: 0 | AW29: 30~39年 | AX29: 0
E30: 40~49年 | F30: 25.823963 | G30: 24.536447 | H30: 24.649632 | K30: 40~49年 | L30: -0.11416097 | M30: 0.59744979 | N30: 0.54416549 | Q30: 40~49年 | R30: 25.938124 | S30: 23.938998 | T30: 24.105467 | W30: 40~49年 | X30: 1.2825899 | Y30: 0.53697657 | Z30: 0.59489839 | AC30: 40~49年 | AD30: 24.655534 | AE30: 23.402021 | AF30: 23.510568 | AI30: 40~49年 | AJ30: 24.655534 | AK30: 23.402021 | AL30: 23.510568 | AO30: 40~49年 | AP30: 0 | AS30: 40~49年 | AT30: 0 | AW30: 40~49年 | AX30: 0
E31: 50年以上 | F31: 9.018311 | G31: 6.8285006 | H31: 7.0210054 | K31: 50年以上 | L31: 1.2620732 | M31: 1.262864 | N31: 1.2729556 | Q31: 50年以上 | R31: 7.7562379 | S31: 5.5656366 | T31: 5.7480498 | W31: 50年以上 | X31: 1.4718049 | Y31: 1.0719226 | Z31: 1.0992697 | AC31: 50年以上 | AD31: 6.2844329 | AE31: 4.493714 | AF31: 4.6487801 | AI31: 50年以上 | AJ31: 6.2844329 | AK31: 4.493714 | AL31: 4.6487801 | AO31: 50年以上 | AP31: 0 | AS31: 50年以上 | AT31: 0 | AW31: 50年以上 | AX31: 0
E32: 總計 | F32: 100 | G32: 100 | H32: 100 | K32: 總計 | L32: 0 | M32: 0 | N32: 0 | Q32: 總計 | R32: 100 | S32: 100 | T32: 100 | W32: 總計 | X32: 0 | Y32: 0 | Z32: 0 | AC32: 總計 | AD32: 100 | AE32: 100 | AF32: 100 | AI32: 總計 | AJ32: 100 | AK32: 100 | AL32: 100 | AO32: 總計 | AP32: 0 | AS32: 總計 | AT32: 0 | AW32: 總計 | AX32: 0
F34: 低度用電 | G34: 非低度用電 | H34: 總計 | L34: 低度用電 | M34: 非低度用電 | N34: 總計 | R34: 低度用電 | S34: 非低度用電 | T34: 總計 | X34: 低度用電 | Y34: 非低度用電 | Z34: 總計 | AD34: 低度用電 | AE34: 非低度用電 | AF34: 總計 | AJ34: 低度用電 | AK34: 非低度用電 | AL34: 總計 | AP34: 總計 | AT34: 總計 | AX34: 總計
E35: 0~4年 | F35: 1.2024292 | G35: 5.2225786 | H35: 6.4250078 | K35: 0~4年 | L35: 0.2827176 | M35: 0.12677623 | N35: 0.40949383 | Q35: 0~4年 | R35: 0.91971156 | S35: 5.0958024 | T35: 6.0155139 | W35: 0~4年 | X35: -0.20224338 | Y35: 0.044495085 | Z35: -0.15774829 | AC35: 0~4年 | AD35: 1.1219549 | AE35: 5.0513073 | AF35: 6.1732622 | AI35: 0~4年 | AJ35: 1.1219549 | AK35: 5.0513073 | AL35: 6.1732622 | AO35: 0~4年 | AP35: 0 | AS35: 0~4年 | AT35: 0 | AW35: 0~4年 | AX35: 0
